Workbook

Sheet Rice
A1: Rep | B1: Scenarios | C1: Seedbed Preparation | D1: Puddling | E1: Nursery Raising & Transplanting /Sowing | F1: Total energy (MJ/ha) | G1: Seed | H1: Fertilizers | I1: Pesticides | J1: Irrigation(Diesel/electricity) | K1: Total energy(MJ/ha) | L1: Interculture/Weeding | M1: Inputs application | N1: Total energy(MJ/ha) | O1: Harvesting/Threshing | P1: Transportation | Q1: Engergy used in crop residue | R1: Total energy of different sources(MJ/ha) | S1: Direct energy | T1: Indirect energy | U1: Total energy input | V1: Direct energy | W1: Indirect energy | X1: Total energy input | Y1: Renewable energy | Z1: Non-renewable energy | AA1: Total energy input | AB1: Renewable energy | AC1: Non-renewable energy | AD1: Total energy input | AE1: Grain yield | AF1: Grain energy output | AG1: Energy in the harvested total biomass (grain + straw) | AH1: Net energy MJ ha−1 | AI1: Total speciﬁc energy (MJ ha-1) | AJ1: Grain speciﬁc energy | AK1: Energy productivity(kg MJ-1)
A2: 1 | B2: 1 | C2: 1976.7884 | D2: 1381.2323 | E2: =188.16+789.58 -> 977.74 | F2: =SUM(C2:E2) -> 4335.7608 | G2: 183.75 | H2: 14747.9 | I2: 1993.2 | J2: 19542.823 | K2: =SUM(G2:J2) -> 36467.673 | L2: 47.04 | M2: 2290.5159 | N2: =SUM(L2:M2) -> 2337.5559 | O2: 1126.2 | P2: 385 | Q2: =(AG2-AF2) -> 120815.44 | R2: =(F2+K2+N2+O2+P2) -> 44652.189 | S2: =F2+J2+L2+M2+O2+P2 -> 27727.339 | T2: =G2+H2+I2 -> 16924.85 | U2: =S2+T2 -> 44652.189 | V2: =(S2+S8+S14)/3 -> 28760.143 | W2: =(T2+T8+T14)/3 -> 16924.85 | X2: =(U2+U8+U14)/3 -> 45684.993 | Y2: =G2+L2+M2 -> 2521.3059 | Z2: =F2+H2+I2+J2+O2+P2 -> 42130.884 | AA2: =SUM(Y2:Z2) -> 44652.189 | AB2: =(Y2+Y8+Y14)/3 -> 2624.4138 | AC2: =(Z2+Z8+Z14)/3 -> 43060.579 | AD2: =(AA2+AA8+AA14)/3 -> 45684.993 | AE2: 6657 | AF2: 97857.9 | AG2: 218673.34 | AH2: =AG2-U2 -> 174021.15 | AI2: =AG2/U2 -> 4.897259 | AJ2: =AF2/AA2 -> 2.1915588 | AK2: =(AE2+AE8+AE14)/3 -> 6725.6667 | AL2: =(AF2+AF8+AF14)/3 -> 98867.3 | AM2: =(AG2+AG8+AG14)/3 -> 217461.42 | AN2: =(AH2+AH8+AH14)/3 -> 171776.43 | AO2: =(AI2+AI8+AI14)/3 -> 4.7692431 | AP2: =(AJ2+AJ8+AJ14)/3 -> 2.1674738 | AQ2: =(#REF!+#REF!+#REF!)/3 -> #REF!
A3: 1 | B3: 2 | C3: 1976.7884 | D3: 1381.2323 | E3: =188.16+789.58 -> 977.74 | F3: =SUM(C3:E3) -> 4335.7608 | G3: 183.75 | H3: 14747.9 | I3: 1993.2 | J3: 19542.823 | K3: =SUM(G3:J3) -> 36467.673 | L3: 47.04 | M3: 2290.5159 | N3: =SUM(L3:M3) -> 2337.5559 | O3: 1126.2 | P3: 385 | Q3: =(AG3-AF3) -> 122329.81 | R3: =(F3+K3+N3+O3+P3) -> 44652.189 | S3: =F3+J3+L3+M3+O3+P3 -> 27727.339 | T3: =G3+H3+I3 -> 16924.85 | U3: =S3+T3 -> 44652.189 | V3: =(S3+S9+S15)/3 -> 28760.143 | W3: =(T3+T9+T15)/3 -> 16924.85 | X3: =(U3+U9+U15)/3 -> 45684.993 | Y3: =G3+L3+M3 -> 2521.3059 | Z3: =F3+H3+I3+J3+O3+P3 -> 42130.884 | AA3: =SUM(Y3:Z3) -> 44652.189 | AB3: =(Y3+Y9+Y15)/3 -> 2624.4138 | AC3: =(Z3+Z9+Z15)/3 -> 43060.579 | AD3: =(AA3+AA9+AA15)/3 -> 45684.993 | AE3: 6751 | AF3: 99239.7 | AG3: 221569.51 | AH3: =AG3-U3 -> 176917.32 | AI3: =AG3/U3 -> 4.9621197 | AJ3: =AF3/AA3 -> 2.2225047 | AK3: =(AE3+AE9+AE15)/3 -> 6849.6667 | AL3: =(AF3+AF9+AF15)/3 -> 100690.1 | AM3: =(AG3+AG9+AG15)/3 -> 220720.03 | AN3: =(AH3+AH9+AH15)/3 -> 175035.04 | AO3: =(AI3+AI9+AI15)/3 -> 4.8405669 | AP3: =(AJ3+AJ9+AJ15)/3 -> 2.2070184 | AQ3: =(#REF!+#REF!+#REF!)/3 -> #REF!
A4: 1 | B4: 3 | C4: 1310.1 | D4: 0 | E4: 422.325 | F4: =SUM(C4:E4) -> 1732.425 | G4: 294 | H4: 13474.3 | I4: 351.4 | J4: 16821.069 | K4: =SUM(G4:J4) -> 30940.769 | L4: 62.72 | M4: 1910.1676 | N4: =SUM(L4:M4) -> 1972.8876 | O4: 1126.2 | P4: 385 | Q4: =(AG4-AF4) -> 121787.23 | R4: =(F4+K4+N4+O4+P4) -> 36157.281 | S4: =F4+J4+L4+M4+O4+P4 -> 22037.581 | T4: =G4+H4+I4 -> 14119.7 | U4: =S4+T4 -> 36157.281 | V4: =(S4+S10+S16)/3 -> 23044.097 | W4: =(T4+T10+T16)/3 -> 14119.7 | X4: =(U4+U10+U16)/3 -> 37163.797 | Y4: =G4+L4+M4 -> 2266.8876 | Z4: =F4+H4+I4+J4+O4+P4 -> 33890.394 | AA4: =SUM(Y4:Z4) -> 36157.281 | AB4: =(Y4+Y10+Y16)/3 -> 2367.5392 | AC4: =(Z4+Z10+Z16)/3 -> 34796.257 | AD4: =(AA4+AA10+AA16)/3 -> 37163.797 | AE4: 6434 | AF4: 94579.8 | AG4: 216367.03 | AH4: =AG4-U4 -> 180209.75 | AI4: =AG4/U4 -> 5.9840515 | AJ4: =AF4/AA4 -> 2.6157885 | AK4: =(AE4+AE10+AE16)/3 -> 6643 | AL4: =(AF4+AF10+AF16)/3 -> 97652.1 | AM4: =(AG4+AG10+AG16)/3 -> 217292.23 | AN4: =(AH4+AH10+AH16)/3 -> 180128.43 | AO4: =(AI4+AI10+AI16)/3 -> 5.861454 | AP4: =(AJ4+AJ10+AJ16)/3 -> 2.631196 | AQ4: =(#REF!+#REF!+#REF!)/3 -> #REF!
A5: 1 | B5: 4 | C5: 1310.1 | D5: 0 | E5: 422.325 | F5: =SUM(C5:E5) -> 1732.425 | G5: 294 | H5: 13474.3 | I5: 341.4 | J5: 15929.13 | K5: =SUM(G5:J5) -> 30038.83 | L5: 62.72 | M5: 1811.0634 | N5: =SUM(L5:M5) -> 1873.7834 | O5: 1126.2 | P5: 385 | Q5: =(AG5-AF5) -> 124863.25 | R5: =(F5+K5+N5+O5+P5) -> 35156.239 | S5: =F5+J5+L5+M5+O5+P5 -> 21046.539 | T5: =G5+H5+I5 -> 14109.7 | U5: =S5+T5 -> 35156.239 | V5: =(S5+S11+S17)/3 -> 21894.021 | W5: =(T5+T11+T17)/3 -> 14109.7 | X5: =(U5+U11+U17)/3 -> 36003.721 | Y5: =G5+L5+M5 -> 2167.7834 | Z5: =F5+H5+I5+J5+O5+P5 -> 32988.455 | AA5: =SUM(Y5:Z5) -> 35156.239 | AB5: =(Y5+Y11+Y17)/3 -> 2252.5316 | AC5: =(Z5+Z11+Z17)/3 -> 33751.19 | AD5: =(AA5+AA11+AA17)/3 -> 36003.721 | AE5: 6622 | AF5: 97343.4 | AG5: 222206.65 | AH5: =AG5-U5 -> 187050.41 | AI5: =AG5/U5 -> 6.3205468 | AJ5: =AF5/AA5 -> 2.7688798 | AK5: =(AE5+AE11+AE17)/3 -> 6647 | AL5: =(AF5+AF11+AF17)/3 -> 97710.9 | AM5: =(AG5+AG11+AG17)/3 -> 221853.83 | AN5: =(AH5+AH11+AH17)/3 -> 185850.11 | AO5: =(AI5+AI11+AI17)/3 -> 6.1825368 | AP5: =(AJ5+AJ11+AJ17)/3 -> 2.7233881 | AQ5: =(#REF!+#REF!+#REF!)/3 -> #REF!
A6: 1 | B6: 5 | C6: 0 | D6: 0 | E6: 422.325 | F6: =SUM(C6:E6) -> 422.325 | G6: 294 | H6: 13626.422 | I6: 541.4 | J6: 14898.083 | K6: =SUM(G6:J6) -> 29359.905 | L6: 62.72 | M6: 1696.5025 | N6: =SUM(L6:M6) -> 1759.2225 | O6: 1126.2 | P6: 385 | Q6: =(AG6-AF6) -> 124318.68 | R6: =(F6+K6+N6+O6+P6) -> 33052.652 | S6: =F6+J6+L6+M6+O6+P6 -> 18590.83 | T6: =G6+H6+I6 -> 14461.822 | U6: =S6+T6 -> 33052.652 | V6: =(S6+S12+S18)/3 -> 19279.759 | W6: =(T6+T12+T18)/3 -> 14472.845 | X6: =(U6+U12+U18)/3 -> 33752.604 | Y6: =G6+L6+M6 -> 2053.2225 | Z6: =F6+H6+I6+J6+O6+P6 -> 30999.43 | AA6: =SUM(Y6:Z6) -> 33052.652 | AB6: =(Y6+Y12+Y18)/3 -> 2122.1154 | AC6: =(Z6+Z12+Z18)/3 -> 31630.489 | AD6: =(AA6+AA12+AA18)/3 -> 33752.604 | AE6: 6711 | AF6: 98651.7 | AG6: 222970.38 | AH6: =AG6-U6 -> 189917.73 | AI6: =AG6/U6 -> 6.7459151 | AJ6: =AF6/AA6 -> 2.9846833 | AK6: =(AE6+AE12+AE18)/3 -> 6730 | AL6: =(AF6+AF12+AF18)/3 -> 98931 | AM6: =(AG6+AG12+AG18)/3 -> 222944.4 | AN6: =(AH6+AH12+AH18)/3 -> 189191.79 | AO6: =(AI6+AI12+AI18)/3 -> 6.6405971 | AP6: =(AJ6+AJ12+AJ18)/3 -> 2.9449776 | AQ6: =(#REF!+#REF!+#REF!)/3 -> #REF!
A7: 1 | B7: 6 | C7: 0 | D7: 0 | E7: 422.325 | F7: =SUM(C7:E7) -> 422.325 | G7: 294 | H7: 12599.089 | I7: 541.4 | J7: 14898.083 | K7: =SUM(G7:J7) -> 28332.571 | L7: 62.72 | M7: 1696.5025 | N7: =SUM(L7:M7) -> 1759.2225 | O7: 1126.2 | P7: 385 | Q7: =(AG7-AF7) -> 128079.9 | R7: =(F7+K7+N7+O7+P7) -> 32025.319 | S7: =F7+J7+L7+M7+O7+P7 -> 18590.83 | T7: =G7+H7+I7 -> 13434.489 | U7: =S7+T7 -> 32025.319 | V7: =(S7+S13+S19)/3 -> 19279.759 | W7: =(T7+T13+T19)/3 -> 13326.231 | X7: =(U7+U13+U19)/3 -> 32605.99 | Y7: =G7+L7+M7 -> 2053.2225 | Z7: =F7+H7+I7+J7+O7+P7 -> 29972.096 | AA7: =SUM(Y7:Z7) -> 32025.319 | AB7: =(Y7+Y13+Y19)/3 -> 2122.1154 | AC7: =(Z7+Z13+Z19)/3 -> 30483.874 | AD7: =(AA7+AA13+AA19)/3 -> 32605.99 | AE7: 6891 | AF7: 101297.7 | AG7: 229377.6 | AH7: =AG7-U7 -> 197352.28 | AI7: =AG7/U7 -> 7.162383 | AJ7: =AF7/AA7 -> 3.1630505 | AK7: =(AE7+AE13+AE19)/3 -> 7008 | AL7: =(AF7+AF13+AF19)/3 -> 103017.6 | AM7: =(AG7+AG13+AG19)/3 -> 228561.87 | AN7: =(AH7+AH13+AH19)/3 -> 195955.88 | AO7: =(AI7+AI13+AI19)/3 -> 7.0486387 | AP7: =(AJ7+AJ13+AJ19)/3 -> 3.1724793 | AQ7: =(#REF!+#REF!+#REF!)/3 -> #REF!
A8: 2 | B8: 1 | C8: 1978.3946 | D8: 1382.2123 | E8: =188.16+789.58 -> 977.74 | F8: =SUM(C8:E8) -> 4338.3469 | G8: 183.75 | H8: 14747.9 | I8: 1993.2 | J8: 22303.482 | K8: =SUM(G8:J8) -> 39228.332 | L8: 47.04 | M8: 2597.2557 | N8: =SUM(L8:M8) -> 2644.2957 | O8: 1126.2 | P8: 385 | Q8: =(AG8-AF8) -> 111608.1 | R8: =(F8+K8+N8+O8+P8) -> 47722.174 | S8: =F8+J8+L8+M8+O8+P8 -> 30797.324 | T8: =G8+H8+I8 -> 16924.85 | U8: =S8+T8 -> 47722.174 | V8: =(V2*100)/X2 -> 62.953152 | W8: =(W2*100)/X2 -> 37.046848 | Y8: =G8+L8+M8 -> 2828.0457 | Z8: =F8+H8+I8+J8+O8+P8 -> 44894.128 | AA8: =SUM(Y8:Z8) -> 47722.174 | AE8: 6545 | AF8: 96211.5 | AG8: 207819.6 | AH8: =AG8-U8 -> 160097.43 | AI8: =AG8/U8 -> 4.3547806 | AJ8: =AF8/AA8 -> 2.0160754 | AL8: =(AL7-AL2)/AL2 -> 0.04197849 | AN8: =(AN7-AN2)/AN2 -> 0.14076117
A9: 2 | B9: 2 | C9: 1978.3946 | D9: 1382.2123 | E9: =188.16+789.58 -> 977.74 | F9: =SUM(C9:E9) -> 4338.3469 | G9: 183.75 | H9: 14747.9 | I9: 1993.2 | J9: 22303.482 | K9: =SUM(G9:J9) -> 39228.332 | L9: 47.04 | M9: 2597.2557 | N9: =SUM(L9:M9) -> 2644.2957 | O9: 1126.2 | P9: 385 | Q9: =(AG9-AF9) -> 112371.42 | R9: =(F9+K9+N9+O9+P9) -> 47722.174 | S9: =F9+J9+L9+M9+O9+P9 -> 30797.324 | T9: =G9+H9+I9 -> 16924.85 | U9: =S9+T9 -> 47722.174 | V9: =(V3*100)/X3 -> 62.953152 | W9: =(W3*100)/X3 -> 37.046848 | Y9: =G9+L9+M9 -> 2828.0457 | Z9: =F9+H9+I9+J9+O9+P9 -> 44894.128 | AA9: =SUM(Y9:Z9) -> 47722.174 | AE9: 6725 | AF9: 98857.5 | AG9: 211228.92 | AH9: =AG9-U9 -> 163506.74 | AI9: =AG9/U9 -> 4.4262216 | AJ9: =AF9/AA9 -> 2.0715213 | AL9: =(AL6-AL2)/AL2 -> 0.00064429796 | AN9: =(AN6-AN2)/AN2 -> 0.10138388
A10: 2 | B10: 3 | C10: 1310.1 | D10: 0 | E10: 422.325 | F10: =SUM(C10:E10) -> 1732.425 | G10: 294 | H10: 13474.3 | I10: 351.4 | J10: 19333.225 | K10: =SUM(G10:J10) -> 33452.925 | L10: 62.72 | M10: 2189.2961 | N10: =SUM(L10:M10) -> 2252.0161 | O10: 1126.2 | P10: 385 | Q10: =(AG10-AF10) -> 107668.48 | R10: =(F10+K10+N10+O10+P10) -> 38948.566 | S10: =F10+J10+L10+M10+O10+P10 -> 24828.866 | T10: =G10+H10+I10 -> 14119.7 | U10: =S10+T10 -> 38948.566 | V10: =(V4*100)/X4 -> 62.006842 | W10: =(W4*100)/X4 -> 37.993158 | Y10: =G10+L10+M10 -> 2546.0161 | Z10: =F10+H10+I10+J10+O10+P10 -> 36402.55 | AA10: =SUM(Y10:Z10) -> 38948.566 | AE10: 6555 | AF10: 96358.5 | AG10: 204026.98 | AH10: =AG10-U10 -> 165078.42 | AI10: =AG10/U10 -> 5.2383695 | AJ10: =AF10/AA10 -> 2.4739935 | AL10: =(AL5-AL2)/AL2 -> -0.011696486 | AN10: =(AN5-AN2)/AN2 -> 0.081930188
A11: 2 | B11: 4 | C11: 1310.1 | D11: 0 | E11: 422.325 | F11: =SUM(C11:E11) -> 1732.425 | G11: 294 | H11: 13474.3 | I11: 341.4 | J11: 18617.004 | K11: =SUM(G11:J11) -> 32726.704 | L11: 62.72 | M11: 2109.716 | N11: =SUM(L11:M11) -> 2172.436 | O11: 1126.2 | P11: 385 | Q11: =(AG11-AF11) -> 118166.1 | R11: =(F11+K11+N11+O11+P11) -> 38142.765 | S11: =F11+J11+L11+M11+O11+P11 -> 24033.065 | T11: =G11+H11+I11 -> 14109.7 | U11: =S11+T11 -> 38142.765 | V11: =(V5*100)/X5 -> 60.81044 | W11: =(W5*100)/X5 -> 39.18956 | Y11: =G11+L11+M11 -> 2466.436 | Z11: =F11+H11+I11+J11+O11+P11 -> 35676.329 | AA11: =SUM(Y11:Z11) -> 38142.765 | AE11: 6277 | AF11: 92271.9 | AG11: 210438 | AH11: =AG11-U11 -> 172295.23 | AI11: =AG11/U11 -> 5.5171143 | AJ11: =AF11/AA11 -> 2.4191193 | AL11: =AVERAGE(AL8:AL10) -> 0.010308767 | AN11: =AVERAGE(AN8:AN10) -> 0.10802508
A12: 2 | B12: 5 | C12: 0 | D12: 0 | E12: 422.325 | F12: =SUM(C12:E12) -> 422.325 | G12: 294 | H12: 13736.655 | I12: 541.4 | J12: 17595.431 | K12: =SUM(G12:J12) -> 32167.487 | L12: 62.72 | M12: 1996.2079 | N12: =SUM(L12:M12) -> 2058.9279 | O12: 1126.2 | P12: 385 | Q12: =(AG12-AF12) -> 113981.27 | R12: =(F12+K12+N12+O12+P12) -> 36159.94 | S12: =F12+J12+L12+M12+O12+P12 -> 21587.884 | T12: =G12+H12+I12 -> 14572.055 | U12: =S12+T12 -> 36159.94 | V12: =(V6*100)/X6 -> 57.120804 | W12: =(W6*100)/X6 -> 42.879196 | Y12: =G12+L12+M12 -> 2352.9279 | Z12: =F12+H12+I12+J12+O12+P12 -> 33807.012 | AA12: =SUM(Y12:Z12) -> 36159.94 | AE12: 6378 | AF12: 93756.6 | AG12: 207737.87 | AH12: =AG12-U12 -> 171577.93 | AI12: =AG12/U12 -> 5.7449728 | AJ12: =AF12/AA12 -> 2.5928307
A13: 2 | B13: 6 | C13: 0 | D13: 0 | E13: 422.325 | F13: =SUM(C13:E13) -> 422.325 | G13: 294 | H13: 12591.805 | I13: 541.4 | J13: 17595.431 | K13: =SUM(G13:J13) -> 31022.636 | L13: 62.72 | M13: 1996.2079 | N13: =SUM(L13:M13) -> 2058.9279 | O13: 1126.2 | P13: 385 | Q13: =(AG13-AF13) -> 113587.92 | R13: =(F13+K13+N13+O13+P13) -> 35015.089 | S13: =F13+J13+L13+M13+O13+P13 -> 21587.884 | T13: =G13+H13+I13 -> 13427.205 | U13: =S13+T13 -> 35015.089 | V13: =(V7*100)/X7 -> 59.1295 | W13: =(W7*100)/X7 -> 40.8705 | Y13: =G13+L13+M13 -> 2352.9279 | Z13: =F13+H13+I13+J13+O13+P13 -> 32662.161 | AA13: =SUM(Y13:Z13) -> 35015.089 | AE13: 6848 | AF13: 100665.6 | AG13: 214253.52 | AH13: =AG13-U13 -> 179238.43 | AI13: =AG13/U13 -> 6.1188911 | AJ13: =AF13/AA13 -> 2.8749206
A14: 3 | B14: 1 | C14: 1978.3946 | D14: 1382.2123 | E14: =188.16+789.58 -> 977.74 | F14: =SUM(C14:E14) -> 4338.3469 | G14: 183.75 | H14: 14747.9 | I14: 1993.2 | J14: 19566.08 | K14: =SUM(G14:J14) -> 36490.93 | L14: 47.04 | M14: 2293.0999 | N14: =SUM(L14:M14) -> 2340.1399 | O14: 1126.2 | P14: 385 | Q14: =(AG14-AF14) -> 123358.84 | R14: =(F14+K14+N14+O14+P14) -> 44680.616 | S14: =F14+J14+L14+M14+O14+P14 -> 27755.766 | T14: =G14+H14+I14 -> 16924.85 | U14: =S14+T14 -> 44680.616 | V14: =(V2-V7)/V7 -> 0.49172736 | W14: =(W2-W7)/W7 -> 0.27004026 | Y14: =G14+L14+M14 -> 2523.8899 | Z14: =F14+H14+I14+J14+O14+P14 -> 42156.726 | AA14: =SUM(Y14:Z14) -> 44680.616 | AE14: 6975 | AF14: 102532.5 | AG14: 225891.34 | AH14: =AG14-U14 -> 181210.72 | AI14: =AG14/U14 -> 5.0556898 | AJ14: =AF14/AA14 -> 2.2947871
A15: 3 | B15: 2 | C15: 1978.3946 | D15: 1382.2123 | E15: =188.16+789.58 -> 977.74 | F15: =SUM(C15:E15) -> 4338.3469 | G15: 183.75 | H15: 14747.9 | I15: 1993.2 | J15: 19566.08 | K15: =SUM(G15:J15) -> 36490.93 | L15: 47.04 | M15: 2293.0999 | N15: =SUM(L15:M15) -> 2340.1399 | O15: 1126.2 | P15: 385 | Q15: =(AG15-AF15) -> 125388.57 | R15: =(F15+K15+N15+O15+P15) -> 44680.616 | S15: =F15+J15+L15+M15+O15+P15 -> 27755.766 | T15: =G15+H15+I15 -> 16924.85 | U15: =S15+T15 -> 44680.616 | V15: =(V2-V6)/V6 -> 0.49172736 | W15: =(W2-W6)/W6 -> 0.16942105 | Y15: =G15+L15+M15 -> 2523.8899 | Z15: =F15+H15+I15+J15+O15+P15 -> 42156.726 | AA15: =SUM(Y15:Z15) -> 44680.616 | AE15: 7073 | AF15: 103973.1 | AG15: 229361.67 | AH15: =AG15-U15 -> 184681.05 | AI15: =AG15/U15 -> 5.1333596 | AJ15: =AF15/AA15 -> 2.3270292
A16: 3 | B16: 3 | C16: 1310.1 | D16: 0 | E16: 422.325 | F16: =SUM(C16:E16) -> 1732.425 | G16: 294 | H16: 13474.3 | I16: 351.4 | J16: 17026.503 | K16: =SUM(G16:J16) -> 31146.203 | L16: 62.72 | M16: 1932.9937 | N16: =SUM(L16:M16) -> 1995.7137 | O16: 1126.2 | P16: 385 | Q16: =(AG16-AF16) -> 129464.67 | R16: =(F16+K16+N16+O16+P16) -> 36385.542 | S16: =F16+J16+L16+M16+O16+P16 -> 22265.842 | T16: =G16+H16+I16 -> 14119.7 | U16: =S16+T16 -> 36385.542 | V16: =(V2-V5)/V5 -> 0.31360716 | W16: =(W2-W5)/W5 -> 0.19951877 | X16: =AVERAGE(W14:W16) -> 0.21299336 | Y16: =G16+L16+M16 -> 2289.7137 | Z16: =F16+H16+I16+J16+O16+P16 -> 34095.828 | AA16: =SUM(Y16:Z16) -> 36385.542 | AE16: 6940 | AF16: 102018 | AG16: 231482.67 | AH16: =AG16-U16 -> 195097.12 | AI16: =AG16/U16 -> 6.3619409 | AJ16: =AF16/AA16 -> 2.803806
A17: 3 | B17: 4 | C17: 1310.1 | D17: 0 | E17: 422.325 | F17: =SUM(C17:E17) -> 1732.425 | G17: 294 | H17: 13474.3 | I17: 341.4 | J17: 15529.459 | K17: =SUM(G17:J17) -> 29639.159 | L17: 62.72 | M17: 1766.6555 | N17: =SUM(L17:M17) -> 1829.3755 | O17: 1126.2 | P17: 385 | Q17: =(AG17-AF17) -> 129399.43 | R17: =(F17+K17+N17+O17+P17) -> 34712.16 | S17: =F17+J17+L17+M17+O17+P17 -> 20602.46 | T17: =G17+H17+I17 -> 14109.7 | U17: =S17+T17 -> 34712.16 | V17: =(V2-V4)/V2 -> 0.1987489 | W17: =(W2-W4)/W2 -> 0.1657415 | Y17: =G17+L17+M17 -> 2123.3755 | Z17: =F17+H17+I17+J17+O17+P17 -> 32588.784 | AA17: =SUM(Y17:Z17) -> 34712.16 | AE17: 7042 | AF17: 103517.4 | AG17: 232916.83 | AH17: =AG17-U17 -> 198204.67 | AI17: =AG17/U17 -> 6.7099493 | AJ17: =AF17/AA17 -> 2.9821653
A18: 3 | B18: 5 | C18: 0 | D18: 0 | E18: 422.325 | F18: =SUM(C18:E18) -> 422.325 | G18: 294 | H18: 13549.259 | I18: 541.4 | J18: 14060.841 | K18: =SUM(G18:J18) -> 28445.499 | L18: 62.72 | M18: 1603.4756 | N18: =SUM(L18:M18) -> 1666.1956 | O18: 1126.2 | P18: 385 | Q18: =(AG18-AF18) -> 133740.24 | R18: =(F18+K18+N18+O18+P18) -> 32045.22 | S18: =F18+J18+L18+M18+O18+P18 -> 17660.561 | T18: =G18+H18+I18 -> 14384.659 | U18: =S18+T18 -> 32045.22 | Y18: =G18+L18+M18 -> 1960.1956 | Z18: =F18+H18+I18+J18+O18+P18 -> 30085.024 | AA18: =SUM(Y18:Z18) -> 32045.22 | AE18: 7101 | AF18: 104384.7 | AG18: 238124.94 | AH18: =AG18-U18 -> 206079.72 | AI18: =AG18/U18 -> 7.4309035 | AJ18: =AF18/AA18 -> 3.2574187
A19: 3 | B19: 6 | C19: 0 | D19: 0 | E19: 422.325 | F19: =SUM(C19:E19) -> 422.325 | G19: 294 | H19: 12281.6 | I19: 541.4 | J19: 14060.841 | K19: =SUM(G19:J19) -> 27177.841 | L19: 62.72 | M19: 1603.4756 | N19: =SUM(L19:M19) -> 1666.1956 | O19: 1126.2 | P19: 385 | Q19: =(AG19-AF19) -> 134965 | R19: =(F19+K19+N19+O19+P19) -> 30777.561 | S19: =F19+J19+L19+M19+O19+P19 -> 17660.561 | T19: =G19+H19+I19 -> 13117 | U19: =S19+T19 -> 30777.561 | Y19: =G19+L19+M19 -> 1960.1956 | Z19: =F19+H19+I19+J19+O19+P19 -> 28817.366 | AA19: =SUM(Y19:Z19) -> 30777.561 | AE19: 7285 | AF19: 107089.5 | AG19: 242054.5 | AH19: =AG19-U19 -> 211276.94 | AI19: =AG19/U19 -> 7.864642 | AJ19: =AF19/AA19 -> 3.4794667
R20: =AVERAGE(R2:R19) -> 38482.683 | S20: =AVERAGE(S2:S19) -> 23502.987 | T20: =AVERAGE(T2:T19) -> 14979.696 | U20: =(U2+U8+U14)/3 -> 45684.993
D21: Field operations | E21: Production Inputs | F21: Crop management | G21: Harvesting and | H21: Transportation | I21: total | K21: Field operations | L21: Production Inputs | M21: Crop management | N21: Harvesting and | O21: Transportation | P21: total | R21: =(S20*100)/R20 -> 61.07419
G22: Threshing | N22: Threshing
C23: Sc1 | D23: =(F2+F8+F14)/3 -> 4337.4849 | E23: =(K2+K8+K14)/3 -> 37395.645 | F23: =(N2+N8+N14)/3 -> 2440.6638 | G23: =(O2+O8+O14)/3 -> 1126.2 | H23: =(P2+P8+P14)/3 -> 385 | I23: =SUM(D23:H23) -> 45684.993 | J23: Sc1 | K23: =(D23*100)/I23 -> 9.4943318 | L23: =(E23*100)/I23 -> 81.855423 | M23: =(F23*100)/I23 -> 5.3423754 | N23: =(G23*100)/I23 -> 2.4651421 | O23: =(H23*100)/I23 -> 0.8427275 | P23: =SUM(K23:N23) -> 99.157273
C24: Sc2 | D24: =(F3+F9+F15)/3 -> 4337.4849 | E24: =(K3+K9+K15)/3 -> 37395.645 | F24: =(N3+N9+N15)/3 -> 2440.6638 | G24: =(O3+O9+O15)/3 -> 1126.2 | H24: =(P3+P9+P15)/3 -> 385 | I24: =SUM(D24:H24) -> 45684.993 | J24: Sc2 | K24: =(D24*100)/I24 -> 9.4943318 | L24: =(E24*100)/I24 -> 81.855423 | M24: =(F24*100)/I24 -> 5.3423754 | N24: =(G24*100)/I24 -> 2.4651421 | O24: =(H24*100)/I24 -> 0.8427275 | P24: =SUM(K24:N24) -> 99.157273
C25: Sc3 | D25: =(F4+F10+F16)/3 -> 1732.425 | E25: =(K4+K10+K16)/3 -> 31846.632 | F25: =(N4+N10+N16)/3 -> 2073.5392 | G25: =(O4+O10+O16)/3 -> 1126.2 | H25: =(P4+P10+P16)/3 -> 385 | I25: =SUM(D25:H25) -> 37163.797 | J25: Sc3 | K25: =(D25*100)/I25 -> 4.6615932 | L25: =(E25*100)/I25 -> 85.692624 | M25: =(F25*100)/I25 -> 5.57946 | N25: =(G25*100)/I25 -> 3.0303685 | O25: =(H25*100)/I25 -> 1.0359544 | P25: =SUM(K25:N25) -> 98.964046 | Q25: =(I23-I25)/I23 -> 0.1865207 | R25: =(I23-I25)/I25 -> 0.22928758
C26: Sc4 | D26: =(F5+F11+F17)/3 -> 1732.425 | E26: =(K5+K11+K17)/3 -> 30801.565 | F26: =(N5+N11+N17)/3 -> 1958.5316 | G26: =(O5+O11+O17)/3 -> 1126.2 | H26: =(P5+P11+P17)/3 -> 385 | I26: =SUM(D26:H26) -> 36003.721 | J26: Sc4 | K26: =(D26*100)/I26 -> 4.8117943 | L26: =(E26*100)/I26 -> 85.551059 | M26: =(F26*100)/I26 -> 5.4398033 | N26: =(G26*100)/I26 -> 3.12801 | O26: =(H26*100)/I26 -> 1.0693339 | P26: =SUM(K26:N26) -> 98.930666 | Q26: =(I23-I26)/I23 -> 0.21191361 | R26: =(I23-I26)/I26 -> 0.26889642
C27: Sc5 | D27: =(F6+F12+F18)/3 -> 422.325 | E27: =(K6+K12+K18)/3 -> 29990.964 | F27: =(N6+N12+N18)/3 -> 1828.1154 | G27: =(O6+O12+O18)/3 -> 1126.2 | H27: =(P6+P12+P18)/3 -> 385 | I27: =SUM(D27:H27) -> 33752.604 | J27: Sc5 | K27: =(D27*100)/I27 -> 1.2512368 | L27: =(E27*100)/I27 -> 88.855259 | M27: =(F27*100)/I27 -> 5.4162202 | N27: =(G27*100)/I27 -> 3.3366315 | O27: =(H27*100)/I27 -> 1.1406527 | P27: =SUM(K27:N27) -> 98.859347 | Q27: =(I23-I27)/I23 -> 0.26118838 | R27: =(I23-I27)/I27 -> 0.353525
C28: Sc6 | D28: =(F7+F13+F19)/3 -> 422.325 | E28: =(K7+K13+K19)/3 -> 28844.349 | F28: =(N7+N13+N19)/3 -> 1828.1154 | G28: =(O7+O13+O19)/3 -> 1126.2 | H28: =(P7+P13+P19)/3 -> 385 | I28: =SUM(D28:H28) -> 32605.99 | J28: Sc6 | K28: =(D28*100)/I28 -> 1.2952375 | L28: =(E28*100)/I28 -> 88.463346 | M28: =(F28*100)/I28 -> 5.6066857 | N28: =(G28*100)/I28 -> 3.4539666 | O28: =(H28*100)/I28 -> 1.1807647 | P28: =SUM(K28:N28) -> 98.819235 | Q28: =(I23-I28)/I23 -> 0.28628665 | R28: =(I23-I28)/I28 -> 0.40112273
D29: =AVERAGE(D23:D28) -> 2164.0783 | E29: =AVERAGE(E23:E28) -> 32712.467 | F29: =AVERAGE(F23:F28) -> 2094.9382 | G29: =AVERAGE(G23:G28) -> 1126.2 | H29: =AVERAGE(H23:H28) -> 385 | I29: =AVERAGE(I23:I28) -> 38482.683 | K29: =(F23-F28)/F23 -> 0.25097618 | Q29: =AVERAGE(Q26:Q28) -> 0.25312955
E30: =(E29*100)/I29 -> 85.00568 | F30: =(I38*100)/I29 -> 46.07987 | G30: =(G38*100)/I29 -> 35.761833 | K30: =(F26-F23)/F24 -> -0.19754142 | L30: =(F23-F25)/F23 -> 0.15042002
C31: =C1 -> Seedbed Preparation | D31: =D1 -> Puddling | E31: =E1 -> Nursery Raising & Transplanting /Sowing | F31: =G1 -> Seed | G31: =H1 -> Fertilizers | H31: =I1 -> Pesticides | I31: =J1 -> Irrigation(Diesel/electricity) | J31: =L1 -> Interculture/Weeding | K31: =M1 -> Inputs application | L31: =O1 -> Harvesting/Threshing | M31: =P1 -> Transportation | P31: Tillage | Q31: Puddling | R31: Nursery raising & transplanting /sowing | S31: Seed | T31: Fertilizers | U31: Pesticides | V31: Irrigation (electricity) | W31: Weeding | X31: Inputs application | Y31: Harvesting & threshing | Z31: Transportation
B32: Sc1 | C32: =(C2+C8+C14)/3 -> 1977.8592 | D32: =(D2+D8+D14)/3 -> 1381.8857 | E32: =(E2+E8+E14)/3 -> 977.74 | F32: =(G2+G8+G14)/3 -> 183.75 | G32: =(H2+H8+H14)/3 -> 14747.9 | H32: =(I2+I8+I14)/3 -> 1993.2 | I32: =(J2+J8+J14)/3 -> 20470.795 | J32: =(L2+L8+L14)/3 -> 47.04 | K32: =(M2+M8+M14)/3 -> 2393.6238 | L32: =(O2+O8+O14)/3 -> 1126.2 | M32: =(P2+P8+P14)/3 -> 385 | N32: =SUM(D32:M32) -> 43707.134 | O32: Sc1 | P32: =(C32*100)/N32 -> 4.5252548 | Q32: =(D32*100)/N32 -> 3.1616936 | R32: =(E32*100)/N32 -> 2.2370261 | S32: =(F32*100)/N32 -> 0.42041192 | T32: =(G32*100)/N32 -> 33.742546 | U32: =(H32*100)/N32 -> 4.5603539 | V32: =(I32*100)/N32 -> 46.836277 | W32: =(J32*100)/N32 -> 0.10762545 | X32: =(K32*100)/N32 -> 5.4765061 | Y32: =(L32*100)/N32 -> 2.5766961 | Z32: =(M32*100)/N32 -> 0.88086306
B33: Sc2 | C33: =(C3+C9+C15)/3 -> 1977.8592 | D33: =(D3+D9+D15)/3 -> 1381.8857 | E33: =(E3+E9+E15)/3 -> 977.74 | F33: =(G3+G9+G15)/3 -> 183.75 | G33: =(H3+H9+H15)/3 -> 14747.9 | H33: =(I3+I9+I15)/3 -> 1993.2 | I33: =(J3+J9+J15)/3 -> 20470.795 | J33: =(L3+L9+L15)/3 -> 47.04 | K33: =(M3+M9+M15)/3 -> 2393.6238 | L33: =(O3+O9+O15)/3 -> 1126.2 | M33: =(P3+P9+P15)/3 -> 385 | N33: =SUM(D33:M33) -> 43707.134 | O33: Sc2 | P33: =(C33*100)/N33 -> 4.5252548 | Q33: =(D33*100)/N33 -> 3.1616936 | R33: =(E33*100)/N33 -> 2.2370261 | S33: =(F33*100)/N33 -> 0.42041192 | T33: =(G33*100)/N33 -> 33.742546 | U33: =(H33*100)/N33 -> 4.5603539 | V33: =(I33*100)/N33 -> 46.836277 | W33: =(J33*100)/N33 -> 0.10762545 | X33: =(K33*100)/N33 -> 5.4765061 | Y33: =(L33*100)/N33 -> 2.5766961 | Z33: =(M33*100)/N33 -> 0.88086306
B34: Sc3 | C34: =(C4+C10+C16)/3 -> 1310.1 | D34: =(D4+D10+D16)/3 -> 0 | E34: =(E4+E10+E16)/3 -> 422.325 | F34: =(G4+G10+G16)/3 -> 294 | G34: =(H4+H10+H16)/3 -> 13474.3 | H34: =(I4+I10+I16)/3 -> 351.4 | I34: =(J4+J10+J16)/3 -> 17726.932 | J34: =(L4+L10+L16)/3 -> 62.72 | K34: =(M4+M10+M16)/3 -> 2010.8192 | L34: =(O4+O10+O16)/3 -> 1126.2 | M34: =(P4+P10+P16)/3 -> 385 | N34: =SUM(D34:M34) -> 35853.697 | O34: Sc3 | P34: =(C34*100)/N34 -> 3.6540165 | Q34: =(D34*100)/N34 -> 0 | R34: =(E34*100)/N34 -> 1.177912 | S34: =(F34*100)/N34 -> 0.81999913 | T34: =(G34*100)/N34 -> 37.581341 | U34: =(H34*100)/N34 -> 0.9800942 | V34: =(I34*100)/N34 -> 49.442412 | W34: =(J34*100)/N34 -> 0.17493315 | X34: =(K34*100)/N34 -> 5.6084012 | Y34: =(L34*100)/N34 -> 3.1410987 | Z34: =(M34*100)/N34 -> 1.0738084
B35: Sc4 | C35: =(C5+C11+C17)/3 -> 1310.1 | D35: =(D5+D11+D17)/3 -> 0 | E35: =(E5+E11+E17)/3 -> 422.325 | F35: =(G5+G11+G17)/3 -> 294 | G35: =(H5+H11+H17)/3 -> 13474.3 | H35: =(I5+I11+I17)/3 -> 341.4 | I35: =(J5+J11+J17)/3 -> 16691.865 | J35: =(L5+L11+L17)/3 -> 62.72 | K35: =(M5+M11+M17)/3 -> 1895.8116 | L35: =(O5+O11+O17)/3 -> 1126.2 | M35: =(P5+P11+P17)/3 -> 385 | N35: =SUM(D35:M35) -> 34693.621 | O35: Sc4 | P35: =(C35*100)/N35 -> 3.7761985 | Q35: =(D35*100)/N35 -> 0 | R35: =(E35*100)/N35 -> 1.2172987 | S35: =(F35*100)/N35 -> 0.84741802 | T35: =(G35*100)/N35 -> 38.837975 | U35: =(H35*100)/N35 -> 0.98404256 | V35: =(I35*100)/N35 -> 48.112201 | W35: =(J35*100)/N35 -> 0.18078251 | X35: =(K35*100)/N35 -> 5.4644386 | Y35: =(L35*100)/N35 -> 3.2461298 | Z35: =(M35*100)/N35 -> 1.1097141
B36: Sc5 | C36: =(C6+C12+C18)/3 -> 0 | D36: =(D6+D12+D18)/3 -> 0 | E36: =(E6+E12+E18)/3 -> 422.325 | F36: =(G6+G12+G18)/3 -> 294 | G36: =(H6+H12+H18)/3 -> 13637.445 | H36: =(I6+I12+I18)/3 -> 541.4 | I36: =(J6+J12+J18)/3 -> 15518.118 | J36: =(L6+L12+L18)/3 -> 62.72 | K36: =(M6+M12+M18)/3 -> 1765.3954 | L36: =(O6+O12+O18)/3 -> 1126.2 | M36: =(P6+P12+P18)/3 -> 385 | N36: =SUM(D36:M36) -> 33752.604 | O36: Sc5 | P36: =(C36*100)/N36 -> 0 | Q36: =(D36*100)/N36 -> 0 | R36: =(E36*100)/N36 -> 1.2512368 | S36: =(F36*100)/N36 -> 0.87104391 | T36: =(G36*100)/N36 -> 40.404128 | U36: =(H36*100)/N36 -> 1.6040244 | V36: =(I36*100)/N36 -> 45.976062 | W36: =(J36*100)/N36 -> 0.1858227 | X36: =(K36*100)/N36 -> 5.2303975 | Y36: =(L36*100)/N36 -> 3.3366315 | Z36: =(M36*100)/N36 -> 1.1406527
B37: Sc6 | C37: =(C7+C13+C19)/3 -> 0 | D37: =(D7+D13+D19)/3 -> 0 | E37: =(E7+E13+E19)/3 -> 422.325 | F37: =(G7+G13+G19)/3 -> 294 | G37: =(H7+H13+H19)/3 -> 12490.831 | H37: =(I7+I13+I19)/3 -> 541.4 | I37: =(J7+J13+J19)/3 -> 15518.118 | J37: =(L7+L13+L19)/3 -> 62.72 | K37: =(M7+M13+M19)/3 -> 1765.3954 | L37: =(O7+O13+O19)/3 -> 1126.2 | M37: =(P7+P13+P19)/3 -> 385 | N37: =SUM(D37:M37) -> 32605.99 | O37: Sc6 | P37: =(C37*100)/N37 -> 0 | Q37: =(D37*100)/N37 -> 0 | R37: =(E37*100)/N37 -> 1.2952375 | S37: =(F37*100)/N37 -> 0.90167482 | T37: =(G37*100)/N37 -> 38.308394 | U37: =(H37*100)/N37 -> 1.6604311 | V37: =(I37*100)/N37 -> 47.592845 | W37: =(J37*100)/N37 -> 0.1923573 | X37: =(K37*100)/N37 -> 5.4143284 | Y37: =(L37*100)/N37 -> 3.4539666 | Z37: =(M37*100)/N37 -> 1.1807647
G38: =AVERAGE(G32:G37) -> 13762.113 | I38: =AVERAGE(I32:I37) -> 17732.77
C39: =((C32-C34)/C32)*100 -> 33.761715 | D39: =((D32-D34)/D32)*100 -> 100 | E39: =((E32-E34)/E32)*100 -> 56.806002 | F39: =((F32-F34)/F32)*100 -> -60 | G39: =((G32-G34)/G32)*100 -> 8.6358058 | H39: =((H32-H34)/H32)*100 -> 82.370058 | I39: =((I32-I34)/I32)*100 -> 13.40379 | J39: =((J32-J34)/J32)*100 -> -33.333333 | ... N39: =((N32-N34)/N32)*100 -> 17.96832
C40: =((C32-C35)/C32)*100 -> 33.761715 | D40: =((D32-D35)/D32)*100 -> 100 | E40: =((E32-E35)/E32)*100 -> 56.806002 | F40: =((F32-F35)/F32)*100 -> -60 | G40: =((G32-G35)/G32)*100 -> 8.6358058 | H40: =((H32-H35)/H32)*100 -> 82.871764 | I40: =((I32-I35)/I32)*100 -> 18.460104 | J40: =((J32-J35)/J32)*100 -> -33.333333 | ... N40: =((N32-N35)/N32)*100 -> 20.622521
...

Sheet Wheat
A1: Rep | B1: Scenarios | C1: Tillage | D1: Sowing | E1: Total energy (MJ/ha) | F1: Seed | G1: Fertilizers | H1: Pesticides | I1: Irrigation | J1: Total energy(MJ/ha) | K1: Weeding | L1: Inputs application | M1: Total energy(MJ/ha) | N1: Harvesting & threshing | O1: Transportation | P1: Total energy of different sources(MJ/ha) | Q1: Tillage operations | R1: Planting/Sowing | S1: Total energy (MJ/ha) | T1: Seed | U1: Fertilizers | V1: Pesticides | W1: Irrigation | X1: Total energy(MJ/ha) | Y1: Interculture /Weeding | Z1: Inputs application | AA1: Total energy(MJ/ha) | AB1: Harvesting/ Threshing | AC1: Transportation | AD1: Total energy of different sources(MJ/ha) | AE1: Direct energy | AF1: Indirect energy | AG1: Total energy input | AH1: Direct energy | AI1: Indirect energy Machinery | AJ1: Total energy input | AK1: Renewable energy | AL1: Non-renewable energy | AM1: Total energy input | AN1: Renewable energy | AO1: Non-renewable energy | AP1: Total energy input | AQ1: Grain yield | AR1: Grain energy output | AS1: Energy in the harvested total biomass (grain + straw) | AT1: Net energy MJ ha−1 | AU1: Total speciﬁc energy (MJ ha-1) | AV1: Grain speciﬁc energy
A2: 1 | B2: 1 | C2: 2228.2002 | D2: 849.90789 | E2: =SUM(C2:D2) -> 3078.1081 | F2: 1470 | G2: 14327.9 | H2: 364 | I2: 3804.1964 | J2: =SUM(F2:I2) -> 19966.096 | K2: 15.68 | L2: 457.96849 | M2: =SUM(K2:L2) -> 473.64849 | N2: 844.65 | O2: 369.22 | P2: =SUM(E2+J2+M2+N2+O2) -> 24731.723 | Q2: =(C2+C8+C14)/3 -> 2228.2002 | R2: =(D2+D8+D14)/3 -> 849.90789 | S2: =(E2+E8+E14)/3 -> 3078.1081 | T2: =(F2+F8+F14)/3 -> 1470 | U2: =(G2+G8+G14)/3 -> 14327.9 | V2: =(H2+H8+H14)/3 -> 364 | W2: =(I2+I8+I14)/3 -> 3927.9452 | X2: =(J2+J8+J14)/3 -> 20089.845 | ... AD2: =(P2+P8+P14)/3 -> 24869.222 | AE2: =E2+I2+N2+O2+K2+L2 -> 8569.823 | AF2: =G2+F2+H2 -> 16161.9 | AG2: =SUM(AE2:AF2) -> 24731.723 | AH2: =(AE2+AE8+AE14)/3 -> 8707.3216 | AI2: =(AF2+AF8+AF14)/3 -> 16161.9 | AJ2: =(AG2+AG8+AG14)/3 -> 24869.222 | AK2: =F2+K2+L2 -> 1943.6485 | AL2: =E2+G2+H2+I2+N2+O2 -> 22788.075 | AM2: =SUM(AK2:AL2) -> 24731.723 | AN2: =(AK2+AK8+AK14)/3 -> 1957.3984 | AO2: =(AL2+AL8+AL14)/3 -> 22911.823 | AP2: =(AM2+AM8+AM14)/3 -> 24869.222 | AQ2: 5222 | AR2: =(AQ2*14.7) -> 76763.4 | AS2: 158254.17 | AT2: =AS2-AR2 -> 81490.767 | AU2: =AS2/AM2 -> 6.398833 | AV2: =AR2/AM2 -> 3.1038436 | AZ2: =(AQ2+AQ8+AQ14)/3 -> 5061.3333 | BA2: =(AR2+AR8+AR14)/3 -> 74401.6 | BB2: =(AS2+AS8+AS14)/3 -> 153780.03 | BC2: =(AT2+AT8+AT14)/3 -> 79378.428 | BD2: =(AU2+AU8+AU14)/3 -> 6.1856567 | BE2: =(AV2+AV8+AV14)/3 -> 2.993442
A3: 1 | B3: 2 | C3: 2228.2002 | D3: 849.90789 | E3: =SUM(C3:D3) -> 3078.1081 | F3: 1470 | G3: 14327.9 | H3: 364 | I3: 3804.1964 | J3: =SUM(F3:I3) -> 19966.096 | K3: 15.68 | L3: 457.96849 | M3: =SUM(K3:L3) -> 473.64849 | N3: 844.65 | O3: 369.22 | P3: =SUM(E3+J3+M3+N3+O3) -> 24731.723 | Q3: =(C3+C9+C15)/3 -> 2228.2002 | R3: =(D3+D9+D15)/3 -> 849.90789 | S3: =(E3+E9+E15)/3 -> 3078.1081 | T3: =(F3+F9+F15)/3 -> 1470 | U3: =(G3+G9+G15)/3 -> 14327.9 | V3: =(H3+H9+H15)/3 -> 364 | W3: =(I3+I9+I15)/3 -> 3927.9452 | X3: =(J3+J9+J15)/3 -> 20089.845 | ... AD3: =(P3+P9+P15)/3 -> 24869.222 | AE3: =E3+I3+N3+O3+K3+L3 -> 8569.823 | AF3: =G3+F3+H3 -> 16161.9 | AG3: =SUM(AE3:AF3) -> 24731.723 | AH3: =(AE3+AE9+AE15)/3 -> 8707.3216 | AI3: =(AF3+AF9+AF15)/3 -> 16161.9 | AJ3: =(AG3+AG9+AG15)/3 -> 24869.222 | AK3: =F3+K3+L3 -> 1943.6485 | AL3: =E3+G3+H3+I3+N3+O3 -> 22788.075 | AM3: =SUM(AK3:AL3) -> 24731.723 | AN3: =(AK3+AK9+AK15)/3 -> 1957.3984 | AO3: =(AL3+AL9+AL15)/3 -> 22911.823 | AP3: =(AM3+AM9+AM15)/3 -> 24869.222 | AQ3: 5290 | AR3: =(AQ3*14.7) -> 77763 | AS3: 160725.5 | AT3: =AS3-AR3 -> 82962.5 | AU3: =AS3/AM3 -> 6.4987587 | AV3: =AR3/AM3 -> 3.1442613 | AZ3: =(AQ3+AQ9+AQ15)/3 -> 5149.6667 | BA3: =(AR3+AR9+AR15)/3 -> 75700.1 | BB3: =(AS3+AS9+AS15)/3 -> 156036.44 | BC3: =(AT3+AT9+AT15)/3 -> 80336.344 | BD3: =(AU3+AU9+AU15)/3 -> 6.2751773 | BE3: =(AV3+AV9+AV15)/3 -> 3.0446187
A4: 1 | B4: 3 | C4: 1382.2123 | D4: 594.10167 | E4: =SUM(C4:D4) -> 1976.314 | F4: 1470 | G4: 12751.8 | H4: 352 | I4: 3586.703 | J4: =SUM(F4:I4) -> 18160.503 | K4: 15.68 | L4: 425.96256 | M4: =SUM(K4:L4) -> 441.64256 | N4: 844.65 | O4: 369.22 | P4: =SUM(E4+J4+M4+N4+O4) -> 21792.33 | Q4: =(C4+C10+C16)/3 -> 1382.2123 | R4: =(D4+D10+D16)/3 -> 594.10167 | S4: =(E4+E10+E16)/3 -> 1976.314 | T4: =(F4+F10+F16)/3 -> 1470 | U4: =(G4+G10+G16)/3 -> 12751.8 | V4: =(H4+H10+H16)/3 -> 352 | W4: =(I4+I10+I16)/3 -> 3830.755 | X4: =(J4+J10+J16)/3 -> 18404.555 | ... AD4: =(P4+P10+P16)/3 -> 22063.498 | AE4: =E4+I4+N4+O4+K4+L4 -> 7218.5296 | AF4: =G4+F4+H4 -> 14573.8 | AG4: =SUM(AE4:AF4) -> 21792.33 | AH4: =(AE4+AE10+AE16)/3 -> 7489.6985 | AI4: =(AF4+AF10+AF16)/3 -> 14573.8 | AJ4: =(AG4+AG10+AG16)/3 -> 22063.498 | AK4: =F4+K4+L4 -> 1911.6426 | AL4: =E4+G4+H4+I4+N4+O4 -> 19880.687 | AM4: =SUM(AK4:AL4) -> 21792.33 | AN4: =(AK4+AK10+AK16)/3 -> 1938.7594 | AO4: =(AL4+AL10+AL16)/3 -> 20124.739 | AP4: =(AM4+AM10+AM16)/3 -> 22063.498 | AQ4: 5308 | AR4: =(AQ4*14.7) -> 78027.6 | AS4: 161437.17 | AT4: =AS4-AR4 -> 83409.567 | AU4: =AS4/AM4 -> 7.4079811 | AV4: =AR4/AM4 -> 3.5805075 | AZ4: =(AQ4+AQ10+AQ16)/3 -> 5386 | BA4: =(AR4+AR10+AR16)/3 -> 79174.2 | BB4: =(AS4+AS10+AS16)/3 -> 162005.32 | BC4: =(AT4+AT10+AT16)/3 -> 82831.122 | BD4: =(AU4+AU10+AU16)/3 -> 7.3446749 | BE4: =(AV4+AV10+AV16)/3 -> 3.5893108
A5: 1 | B5: 4 | D5: 892.36506 | E5: =SUM(C5:D5) -> 892.36506 | F5: 1470 | G5: 12751.8 | H5: 462 | I5: 3002.701 | J5: =SUM(F5:I5) -> 17686.501 | K5: 0 | L5: 366.95344 | M5: =SUM(K5:L5) -> 366.95344 | N5: 844.65 | O5: 369.22 | P5: =SUM(E5+J5+M5+N5+O5) -> 20159.689 | Q5: =(C5+C11+C17)/3 -> 0 | R5: =(D5+D11+D17)/3 -> 892.36506 | S5: =(E5+E11+E17)/3 -> 892.36506 | T5: =(F5+F11+F17)/3 -> 1470 | U5: =(G5+G11+G17)/3 -> 12751.8 | V5: =(H5+H11+H17)/3 -> 462 | W5: =(I5+I11+I17)/3 -> 3235.8424 | X5: =(J5+J11+J17)/3 -> 17919.642 | ... AD5: =(P5+P11+P17)/3 -> 20418.735 | AE5: =E5+I5+N5+O5+K5+L5 -> 5475.8895 | AF5: =G5+F5+H5 -> 14683.8 | AG5: =SUM(AE5:AF5) -> 20159.689 | AH5: =(AE5+AE11+AE17)/3 -> 5734.9355 | AI5: =(AF5+AF11+AF17)/3 -> 14683.8 | AJ5: =(AG5+AG11+AG17)/3 -> 20418.735 | AK5: =F5+K5+L5 -> 1836.9534 | AL5: =E5+G5+H5+I5+N5+O5 -> 18322.736 | AM5: =SUM(AK5:AL5) -> 20159.689 | AN5: =(AK5+AK11+AK17)/3 -> 1862.858 | AO5: =(AL5+AL11+AL17)/3 -> 18555.877 | AP5: =(AM5+AM11+AM17)/3 -> 20418.736 | AQ5: 5739 | AR5: =(AQ5*14.7) -> 84363.3 | AS5: 172278 | AT5: =AS5-AR5 -> 87914.7 | AU5: =AS5/AM5 -> 8.5456674 | AV5: =AR5/AM5 -> 4.184752 | AZ5: =(AQ5+AQ11+AQ17)/3 -> 5635 | BA5: =(AR5+AR11+AR17)/3 -> 82834.5 | BB5: =(AS5+AS11+AS17)/3 -> 169805.39 | BC5: =(AT5+AT11+AT17)/3 -> 86970.889 | BD5: =(AU5+AU11+AU17)/3 -> 8.3174983 | BE5: =(AV5+AV11+AV17)/3 -> 4.0577223
A6: 1 | B6: 5 | C6: 0 | D6: 892.36506 | E6: =SUM(C6:D6) -> 892.36506 | F6: 1470 | G6: 11398.135 | H6: 462 | I6: 3002.701 | J6: =SUM(F6:I6) -> 16332.836 | K6: 0 | L6: 366.95344 | M6: =SUM(K6:L6) -> 366.95344 | N6: 844.65 | O6: 369.22 | P6: =SUM(E6+J6+M6+N6+O6) -> 18806.024 | Q6: =(C6+C12+C18)/3 -> 0 | R6: =(D6+D12+D18)/3 -> 892.36506 | S6: =(E6+E12+E18)/3 -> 892.36506 | T6: =(F6+F12+F18)/3 -> 1470 | U6: =(G6+G12+G18)/3 -> 11597.29 | V6: =(H6+H12+H18)/3 -> 462 | W6: =(I6+I12+I18)/3 -> 3235.8424 | X6: =(J6+J12+J18)/3 -> 16765.132 | ... AD6: =(P6+P12+P18)/3 -> 19264.225 | AE6: =E6+I6+N6+O6+K6+L6 -> 5475.8895 | AF6: =G6+F6+H6 -> 13330.135 | AG6: =SUM(AE6:AF6) -> 18806.024 | AH6: =(AE6+AE12+AE18)/3 -> 5734.9355 | AI6: =(AF6+AF12+AF18)/3 -> 13529.29 | AJ6: =(AG6+AG12+AG18)/3 -> 19264.225 | AK6: =F6+K6+L6 -> 1836.9534 | AL6: =E6+G6+H6+I6+N6+O6 -> 16969.071 | AM6: =SUM(AK6:AL6) -> 18806.024 | AN6: =(AK6+AK12+AK18)/3 -> 1862.858 | AO6: =(AL6+AL12+AL18)/3 -> 17401.367 | AP6: =(AM6+AM12+AM18)/3 -> 19264.225 | AQ6: 5889 | AR6: =(AQ6*14.7) -> 86568.3 | AS6: 176520.5 | AT6: =AS6-AR6 -> 89952.2 | AU6: =AS6/AM6 -> 9.3863806 | AV6: =AR6/AM6 -> 4.6032218 | AZ6: =(AQ6+AQ12+AQ18)/3 -> 5774.6667 | BA6: =(AR6+AR12+AR18)/3 -> 84887.6 | BB6: =(AS6+AS12+AS18)/3 -> 173759.28 | BC6: =(AT6+AT12+AT18)/3 -> 88871.678 | BD6: =(AU6+AU12+AU18)/3 -> 9.0256035 | BE6: =(AV6+AV12+AV18)/3 -> 4.4103437
A7: 1 | B7: 6 | C7: 0 | D7: 892.36506 | E7: =SUM(C7:D7) -> 892.36506 | F7: 1470 | G7: 10612.744 | H7: 462 | I7: 3002.701 | J7: =SUM(F7:I7) -> 15547.445 | K7: 0 | L7: 366.95344 | M7: =SUM(K7:L7) -> 366.95344 | N7: 844.65 | O7: 369.22 | P7: =SUM(E7+J7+M7+N7+O7) -> 18020.634 | Q7: =(C7+C13+C19)/3 -> 0 | R7: =(D7+D13+D19)/3 -> 892.36506 | S7: =(E7+E13+E19)/3 -> 892.36506 | T7: =(F7+F13+F19)/3 -> 1470 | U7: =(G7+G13+G19)/3 -> 10809.358 | V7: =(H7+H13+H19)/3 -> 462 | W7: =(I7+I13+I19)/3 -> 3235.8424 | X7: =(J7+J13+J19)/3 -> 15977.2 | ... AD7: =(P7+P13+P19)/3 -> 18476.293 | AE7: =E7+I7+N7+O7+K7+L7 -> 5475.8895 | AF7: =G7+F7+H7 -> 12544.744 | AG7: =SUM(AE7:AF7) -> 18020.634 | AH7: =(AE7+AE13+AE19)/3 -> 5734.9355 | AI7: =(AF7+AF13+AF19)/3 -> 12741.358 | AJ7: =(AG7+AG13+AG19)/3 -> 18476.293 | AK7: =F7+K7+L7 -> 1836.9534 | AL7: =E7+G7+H7+I7+N7+O7 -> 16183.68 | AM7: =SUM(AK7:AL7) -> 18020.634 | AN7: =(AK7+AK13+AK19)/3 -> 1862.858 | AO7: =(AL7+AL13+AL19)/3 -> 16613.435 | AP7: =(AM7+AM13+AM19)/3 -> 18476.293 | AQ7: 5909 | AR7: =(AQ7*14.7) -> 86862.3 | AS7: 179133 | AT7: =AS7-AR7 -> 92270.7 | AU7: =AS7/AM7 -> 9.9404384 | AV7: =AR7/AM7 -> 4.8201579 | AZ7: =(AQ7+AQ13+AQ19)/3 -> 5847.6667 | BA7: =(AR7+AR13+AR19)/3 -> 85960.7 | BB7: =(AS7+AS13+AS19)/3 -> 175866.39 | BC7: =(AT7+AT13+AT19)/3 -> 89905.689 | BD7: =(AU7+AU13+AU19)/3 -> 9.525838 | BE7: =(AV7+AV13+AV19)/3 -> 4.6562499
A8: 2 | B8: 1 | C8: 2228.2002 | D8: 849.90789 | E8: =SUM(C8:D8) -> 3078.1081 | F8: 1470 | G8: 14327.9 | H8: 364 | I8: 4263.732 | J8: =SUM(F8:I8) -> 20425.632 | K8: 15.68 | L8: 509.028 | M8: =SUM(K8:L8) -> 524.708 | N8: 844.65 | O8: 369.22 | P8: =SUM(E8+J8+M8+N8+O8) -> 25242.318 | AE8: =E8+I8+N8+O8+K8+L8 -> 9080.4181 | AF8: =G8+F8+H8 -> 16161.9 | AG8: =SUM(AE8:AF8) -> 25242.318 | AK8: =F8+K8+L8 -> 1994.708 | AL8: =E8+G8+H8+I8+N8+O8 -> 23247.61 | AM8: =SUM(AK8:AL8) -> 25242.318 | AQ8: 4746 | AR8: =(AQ8*14.7) -> 69766.2 | AS8: 148749.08 | AT8: =AS8-AR8 -> 78982.883 | AU8: =AS8/AM8 -> 5.8928456 | AV8: =AR8/AM8 -> 2.7638587 | BA8: =(BA7-BA2)/BA2 -> 0.15536091 | BC8: =(BC7-BC2)/BC2 -> 0.13262118 | BD8: =AVERAGE(BC5:BC7) -> 88582.752
A9: 2 | B9: 2 | C9: 2228.2002 | D9: 849.90789 | E9: =SUM(C9:D9) -> 3078.1081 | F9: 1470 | G9: 14327.9 | H9: 364 | I9: 4263.732 | J9: =SUM(F9:I9) -> 20425.632 | K9: 15.68 | L9: 509.028 | M9: =SUM(K9:L9) -> 524.708 | N9: 844.65 | O9: 369.22 | P9: =SUM(E9+J9+M9+N9+O9) -> 25242.318 | AE9: =E9+I9+N9+O9+K9+L9 -> 9080.4181 | AF9: =G9+F9+H9 -> 16161.9 | AG9: =SUM(AE9:AF9) -> 25242.318 | AK9: =F9+K9+L9 -> 1994.708 | AL9: =E9+G9+H9+I9+N9+O9 -> 23247.61 | AM9: =SUM(AK9:AL9) -> 25242.318 | AQ9: 5055 | AR9: =(AQ9*14.7) -> 74308.5 | AS9: 154712.33 | AT9: =AS9-AR9 -> 80403.833 | AU9: =AS9/AM9 -> 6.1290858 | AV9: =AR9/AM9 -> 2.9438065 | BA9: =(BA6-BA2)/BA2 -> 0.14093783 | BC9: =(BC6-BC2)/BC2 -> 0.11959484 | BD9: =(BD8-BC2)/BC2 -> 0.11595498
A10: 2 | B10: 3 | C10: 1382.2123 | D10: 594.10167 | E10: =SUM(C10:D10) -> 1976.314 | F10: 1470 | G10: 12751.8 | H10: 352 | I10: 4263.732 | J10: =SUM(F10:I10) -> 18837.532 | K10: 15.68 | L10: 501.188 | M10: =SUM(K10:L10) -> 516.868 | N10: 844.65 | O10: 369.22 | P10: =SUM(E10+J10+M10+N10+O10) -> 22544.584 | AE10: =E10+I10+N10+O10+K10+L10 -> 7970.784 | AF10: =G10+F10+H10 -> 14573.8 | AG10: =SUM(AE10:AF10) -> 22544.584 | AK10: =F10+K10+L10 -> 1986.868 | AL10: =E10+G10+H10+I10+N10+O10 -> 20557.716 | AM10: =SUM(AK10:AL10) -> 22544.584 | AQ10: 5380 | AR10: =(AQ10*14.7) -> 79086 | AS10: 161412.17 | AT10: =AS10-AR10 -> 82326.167 | AU10: =AS10/AM10 -> 7.1596871 | AV10: =AR10/AM10 -> 3.5079822 | BA10: =(BA5-BA2)/BA2 -> 0.11334299 | BC10: =(BC5-BC2)/BC2 -> 0.095648923
A11: 2 | B11: 4 | D11: 892.36506 | E11: =SUM(C11:D11) -> 892.36506 | F11: 1470 | G11: 12751.8 | H11: 462 | I11: 3429.0742 | J11: =SUM(F11:I11) -> 18112.874 | K11: 0 | L11: 414.32824 | M11: =SUM(K11:L11) -> 414.32824 | N11: 844.65 | O11: 369.22 | P11: =SUM(E11+J11+M11+N11+O11) -> 20633.437 | AE11: =E11+I11+N11+O11+K11+L11 -> 5949.6375 | AF11: =G11+F11+H11 -> 14683.8 | AG11: =SUM(AE11:AF11) -> 20633.437 | AK11: =F11+K11+L11 -> 1884.3282 | AL11: =E11+G11+H11+I11+N11+O11 -> 18749.109 | AM11: =SUM(AK11:AL11) -> 20633.437 | AQ11: 5542 | AR11: =(AQ11*14.7) -> 81467.4 | AS11: 170043.5 | AT11: =AS11-AR11 -> 88576.1 | AU11: =AS11/AM11 -> 8.241162 | AV11: =AR11/AM11 -> 3.9483193 | BA11: =AVERAGE(BA8:BA10) -> 0.13654724 | BC11: =AVERAGE(BC8:BC10) -> 0.11595498
A12: 2 | B12: 5 | C12: 0 | D12: 892.36506 | E12: =SUM(C12:D12) -> 892.36506 | F12: 1470 | G12: 11896.389 | H12: 462 | I12: 3429.0742 | J12: =SUM(F12:I12) -> 17257.463 | K12: 0 | L12: 414.32824 | M12: =SUM(K12:L12) -> 414.32824 | N12: 844.65 | O12: 369.22 | P12: =SUM(E12+J12+M12+N12+O12) -> 19778.027 | AE12: =E12+I12+N12+O12+K12+L12 -> 5949.6375 | AF12: =G12+F12+H12 -> 13828.389 | AG12: =SUM(AE12:AF12) -> 19778.027 | AK12: =F12+K12+L12 -> 1884.3282 | AL12: =E12+G12+H12+I12+N12+O12 -> 17893.699 | AM12: =SUM(AK12:AL12) -> 19778.027 | AQ12: 5591 | AR12: =(AQ12*14.7) -> 82187.7 | AS12: 171885.17 | AT12: =AS12-AR12 -> 89697.467 | AU12: =AS12/AM12 -> 8.6907136 | AV12: =AR12/AM12 -> 4.1555055
A13: 2 | B13: 6 | C13: 0 | D13: 892.36506 | E13: =SUM(C13:D13) -> 892.36506 | F13: 1470 | G13: 11117.979 | H13: 462 | I13: 3429.0742 | J13: =SUM(F13:I13) -> 16479.053 | K13: 0 | L13: 414.32824 | M13: =SUM(K13:L13) -> 414.32824 | N13: 844.65 | O13: 369.22 | P13: =SUM(E13+J13+M13+N13+O13) -> 18999.617 | AE13: =E13+I13+N13+O13+K13+L13 -> 5949.6375 | AF13: =G13+F13+H13 -> 13049.979 | AG13: =SUM(AE13:AF13) -> 18999.617 | AK13: =F13+K13+L13 -> 1884.3282 | AL13: =E13+G13+H13+I13+N13+O13 -> 17115.288 | AM13: =SUM(AK13:AL13) -> 18999.617 | AQ13: 5701 | AR13: =(AQ13*14.7) -> 83804.7 | AS13: 173062.5 | AT13: =AS13-AR13 -> 89257.8 | AU13: =AS13/AM13 -> 9.1087364 | AV13: =AR13/AM13 -> 4.4108627
A14: 3 | B14: 1 | C14: 2228.2002 | D14: 849.90789 | E14: =SUM(C14:D14) -> 3078.1081 | F14: 1470 | G14: 14327.9 | H14: 364 | I14: 3715.907 | J14: =SUM(F14:I14) -> 19877.807 | K14: 15.68 | L14: 448.15856 | M14: =SUM(K14:L14) -> 463.83856 | N14: 844.65 | O14: 369.22 | P14: =SUM(E14+J14+M14+N14+O14) -> 24633.624 | AE14: =E14+I14+N14+O14+K14+L14 -> 8471.7237 | AF14: =G14+F14+H14 -> 16161.9 | AG14: =SUM(AE14:AF14) -> 24633.624 | AH14: =(AH2-AH7)/AH7 -> 0.5182946 | AI14: =(AI2-AI7)/AI7 -> 0.26845978 | AK14: =F14+K14+L14 -> 1933.8386 | AL14: =E14+G14+H14+I14+N14+O14 -> 22699.785 | AM14: =SUM(AK14:AL14) -> 24633.624 | AN14: =(AN2-AN7)/AN7 -> 0.05075014 | AO14: =(AO2-AO7)/AO7 -> 0.37911412 | AQ14: 5216 | AR14: =(AQ14*14.7) -> 76675.2 | AS14: 154336.83 | AT14: =AS14-AR14 -> 77661.633 | AU14: =AS14/AM14 -> 6.2652915 | AV14: =AR14/AM14 -> 3.1126237
A15: 3 | B15: 2 | C15: 2228.2002 | D15: 849.90789 | E15: =SUM(C15:D15) -> 3078.1081 | F15: 1470 | G15: 14327.9 | H15: 364 | I15: 3715.907 | J15: =SUM(F15:I15) -> 19877.807 | K15: 15.68 | L15: 448.15856 | M15: =SUM(K15:L15) -> 463.83856 | N15: 844.65 | O15: 369.22 | P15: =SUM(E15+J15+M15+N15+O15) -> 24633.624 | AE15: =E15+I15+N15+O15+K15+L15 -> 8471.7237 | AF15: =G15+F15+H15 -> 16161.9 | AG15: =SUM(AE15:AF15) -> 24633.624 | AH15: =(AH2-AH6)/AH6 -> 0.5182946 | AI15: =(AI2-AI6)/AI6 -> 0.19458601 | AK15: =F15+K15+L15 -> 1933.8386 | AL15: =E15+G15+H15+I15+N15+O15 -> 22699.785 | AM15: =SUM(AK15:AL15) -> 24633.624 | AN15: =(AN2-AN6)/AN6 -> 0.05075014 | AO15: =(AO2-AO6)/AO6 -> 0.31666801 | AQ15: 5104 | AR15: =(AQ15*14.7) -> 75028.8 | AS15: 152671.5 | AT15: =AS15-AR15 -> 77642.7 | AU15: =AS15/AM15 -> 6.1976874 | AV15: =AR15/AM15 -> 3.0457882
A16: 3 | B16: 3 | C16: 1382.2123 | D16: 594.10167 | E16: =SUM(C16:D16) -> 1976.314 | F16: 1470 | G16: 12751.8 | H16: 352 | I16: 3641.8301 | J16: =SUM(F16:I16) -> 18215.63 | K16: 15.68 | L16: 432.08779 | M16: =SUM(K16:L16) -> 447.76779 | N16: 844.65 | O16: 369.22 | P16: =SUM(E16+J16+M16+N16+O16) -> 21853.582 | AE16: =E16+I16+N16+O16+K16+L16 -> 7279.7819 | AF16: =G16+F16+H16 -> 14573.8 | AG16: =SUM(AE16:AF16) -> 21853.582 | AH16: =(AH2-AH5)/AH5 -> 0.5182946 | AI16: =(AI2-AI5)/AI5 -> 0.10066195 | AJ16: =AVERAGE(AI14:AI16) -> 0.18790258 | AK16: =F16+K16+L16 -> 1917.7678 | AL16: =E16+G16+H16+I16+N16+O16 -> 19935.814 | AM16: =SUM(AK16:AL16) -> 21853.582 | AN16: =(AN2-AN5)/AN5 -> 0.05075014 | AO16: =(AO2-AO5)/AO5 -> 0.2347475 | AP16: =AVERAGE(AO14:AO16) -> 0.31017654 | AQ16: 5470 | AR16: =(AQ16*14.7) -> 80409 | AS16: 163166.63 | AT16: =AS16-AR16 -> 82757.633 | AU16: =AS16/AM16 -> 7.4663565 | AV16: =AR16/AM16 -> 3.6794426
A17: 3 | B17: 4 | D17: 892.36506 | E17: =SUM(C17:D17) -> 892.36506 | F17: 1470 | G17: 12751.8 | H17: 462 | I17: 3275.7521 | J17: =SUM(F17:I17) -> 17959.552 | K17: 0 | L17: 397.29245 | M17: =SUM(K17:L17) -> 397.29245 | N17: 844.65 | O17: 369.22 | P17: =SUM(E17+J17+M17+N17+O17) -> 20463.08 | AE17: =E17+I17+N17+O17+K17+L17 -> 5779.2796 | AF17: =G17+F17+H17 -> 14683.8 | AG17: =SUM(AE17:AF17) -> 20463.08 | AH17: =(AH2-AH4)/AH2 -> 0.139839 | AI17: =(AI2-AI4)/AI2 -> 0.098261962 | AK17: =F17+K17+L17 -> 1867.2925 | AL17: =E17+G17+H17+I17+N17+O17 -> 18595.787 | AM17: =SUM(AK17:AL17) -> 20463.08 | AN17: =(AN2-AN4)/AN2 -> 0.0095222836 | AO17: =(AO2-AO4)/AO2 -> 0.12164393 | AQ17: 5624 | AR17: =(AQ17*14.7) -> 82672.8 | AS17: 167094.67 | AT17: =AS17-AR17 -> 84421.867 | AU17: =AS17/AM17 -> 8.1656657 | AV17: =AR17/AM17 -> 4.0400957
A18: 3 | B18: 5 | C18: 0 | D18: 892.36506 | E18: =SUM(C18:D18) -> 892.36506 | F18: 1470 | G18: 11497.345 | H18: 462 | I18: 3275.7521 | J18: =SUM(F18:I18) -> 16705.097 | K18: 0 | L18: 397.29245 | M18: =SUM(K18:L18) -> 397.29245 | N18: 844.65 | O18: 369.22 | P18: =SUM(E18+J18+M18+N18+O18) -> 19208.624 | AE18: =E18+I18+N18+O18+K18+L18 -> 5779.2796 | AF18: =G18+F18+H18 -> 13429.345 | AG18: =SUM(AE18:AF18) -> 19208.624 | AK18: =F18+K18+L18 -> 1867.2925 | AL18: =E18+G18+H18+I18+N18+O18 -> 17341.332 | AM18: =SUM(AK18:AL18) -> 19208.624 | AQ18: 5844 | AR18: =(AQ18*14.7) -> 85906.8 | AS18: 172872.17 | AT18: =AS18-AR18 -> 86965.367 | AU18: =AS18/AM18 -> 8.9997162 | AV18: =AR18/AM18 -> 4.4723036
A19: 3 | B19: 6 | C19: 0 | D19: 892.36506 | E19: =SUM(C19:D19) -> 892.36506 | F19: 1470 | G19: 10697.35 | H19: 462 | I19: 3275.7521 | J19: =SUM(F19:I19) -> 15905.102 | K19: 0 | L19: 397.29245 | M19: =SUM(K19:L19) -> 397.29245 | N19: 844.65 | O19: 369.22 | P19: =SUM(E19+J19+M19+N19+O19) -> 18408.63 | AE19: =E19+I19+N19+O19+K19+L19 -> 5779.2796 | AF19: =G19+F19+H19 -> 12629.35 | AG19: =SUM(AE19:AF19) -> 18408.63 | AK19: =F19+K19+L19 -> 1867.2925 | AL19: =E19+G19+H19+I19+N19+O19 -> 16541.337 | AM19: =SUM(AK19:AL19) -> 18408.63 | AQ19: 5933 | AR19: =(AQ19*14.7) -> 87215.1 | AS19: 175403.67 | AT19: =AS19-AR19 -> 88188.567 | AU19: =AS19/AM19 -> 9.5283392 | AV19: =AR19/AM19 -> 4.7377291
T20: 0
C21: Field operations | D21: Production Inputs | E21: Crop management | F21: Harvesting and | G21: Transportation | H21: total | J21: Field operations | K21: Production Inputs | L21: Crop management | M21: Harvesting and | N21: Transportation | O21: total
F22: Threshing | M22: Threshing
B23: Sc1 | C23: =(E2+E8+E14)/3 -> 3078.1081 | D23: =(J2+J8+J14)/3 -> 20089.845 | E23: =(M2+M8+M14)/3 -> 487.39835 | F23: =(N2+N8+N14)/3 -> 844.65 | G23: =(O2+O8+O14)/3 -> 369.22 | H23: =SUM(C23:G23) -> 24869.222 | I23: Sc1 | J23: =(C23*100)/H23 -> 12.377179 | K23: =(D23*100)/H23 -> 80.781962 | L23: =(E23*100)/H23 -> 1.9598456 | M23: =(F23*100)/H23 -> 3.3963669 | N23: =(G23*100)/H23 -> 1.4846464 | O23: =SUM(J23:M23) -> 98.515354
B24: Sc2 | C24: =(E3+E9+E15)/3 -> 3078.1081 | D24: =(J3+J9+J15)/3 -> 20089.845 | E24: =(M3+M9+M15)/3 -> 487.39835 | F24: =(N3+N9+N15)/3 -> 844.65 | G24: =(O3+O9+O15)/3 -> 369.22 | H24: =SUM(C24:G24) -> 24869.222 | I24: Sc2 | J24: =(C24*100)/H24 -> 12.377179 | K24: =(D24*100)/H24 -> 80.781962 | L24: =(E24*100)/H24 -> 1.9598456 | M24: =(F24*100)/H24 -> 3.3963669 | N24: =(G24*100)/H24 -> 1.4846464 | O24: =SUM(J24:M24) -> 98.515354
B25: Sc3 | C25: =(E4+E10+E16)/3 -> 1976.314 | D25: =(J4+J10+J16)/3 -> 18404.555 | E25: =(M4+M10+M16)/3 -> 468.75945 | F25: =(N4+N10+N16)/3 -> 844.65 | G25: =(O4+O10+O16)/3 -> 369.22 | H25: =SUM(C25:G25) -> 22063.498 | I25: Sc3 | J25: =(H23-H25)/H25 -> 0.12716583 | K25: =(D25*100)/H25 -> 83.416304 | L25: =(E25*100)/H25 -> 2.1245926 | M25: =(F25*100)/H25 -> 3.8282687 | N25: =(G25*100)/H25 -> 1.6734427 | O25: =SUM(J25:M25) -> 89.496331
B26: Sc4 | C26: =(E5+E11+E17)/3 -> 892.36506 | D26: =(J5+J11+J17)/3 -> 17919.642 | E26: =(M5+M11+M17)/3 -> 392.85804 | F26: =(N5+N11+N17)/3 -> 844.65 | G26: =(O5+O11+O17)/3 -> 369.22 | H26: =SUM(C26:G26) -> 20418.735 | I26: Sc4 | J26: =(H23-H26)/H26 -> 0.21796091 | K26: =(D26*100)/H26 -> 87.760784 | L26: =(E26*100)/H26 -> 1.9240077 | M26: =(F26*100)/H26 -> 4.1366421 | N26: =(G26*100)/H26 -> 1.8082413 | O26: =SUM(J26:M26) -> 94.039395
B27: Sc5 | C27: =(E6+E12+E18)/3 -> 892.36506 | D27: =(J6+J12+J18)/3 -> 16765.132 | E27: =(M6+M12+M18)/3 -> 392.85804 | F27: =(N6+N12+N18)/3 -> 844.65 | G27: =(O6+O12+O18)/3 -> 369.22 | H27: =SUM(C27:G27) -> 19264.225 | I27: Sc5 | J27: =(H23-H27)/H27 -> 0.29095365 | K27: =(D27*100)/H27 -> 87.027285 | L27: =(E27*100)/H27 -> 2.039314 | M27: =(F27*100)/H27 -> 4.3845522 | N27: =(G27*100)/H27 -> 1.9166097 | O27: =SUM(J27:M27) -> 93.742104
B28: Sc6 | C28: =(E7+E13+E19)/3 -> 892.36506 | D28: =(J7+J13+J19)/3 -> 15977.2 | E28: =(M7+M13+M19)/3 -> 392.85804 | F28: =(N7+N13+N19)/3 -> 844.65 | G28: =(O7+O13+O19)/3 -> 369.22 | H28: =SUM(C28:G28) -> 18476.293 | I28: Sc6 | J28: =(H23-H28)/H28 -> 0.34600708 | L28: =(E28*100)/H28 -> 2.1262817 | M28: =(F28*100)/H28 -> 4.5715338 | N28: =(G28*100)/H28 -> 1.9983445 | O28: =SUM(J28:M28) -> 7.0438226
C29: =(((C26+C27+C28)/3)-C23)/C23 -> -0.71009301 | D29: =(((D26+D27+D28)/3)-D23)/D23 -> -0.1594099 | H29: =AVERAGE(H26:H28) -> 19386.418 | I29: =(H23-H29)/H23 -> 0.22046543 | K29: =(E23-E28)/E23 -> 0.19396928
C30: =AVERAGE(C23:C28) -> 1801.6042 | D30: =AVERAGE(D23:D28) -> 18207.703 | E30: =AVERAGE(E23:E28) -> 437.02171 | F30: =AVERAGE(F23:F28) -> 844.65 | G30: =AVERAGE(G23:G28) -> 369.22 | H30: =AVERAGE(H23:H29) -> 21335.373 | I30: =(D30*100)/H30 -> 85.340449 | J30: =(D30*100)/H30 -> 85.340449
A31: =(D23-D28)/D23 -> 0.20471262 | C31: =C1 -> Tillage | D31: =D1 -> Sowing | E31: =F1 -> Seed | F31: =G1 -> Fertilizers | G31: =H1 -> Pesticides | H31: =I1 -> Irrigation | I31: =K1 -> Weeding | J31: =L1 -> Inputs application | K31: =N1 -> Harvesting & threshing | L31: =O1 -> Transportation
A32: =(D23-D27)/D23 -> 0.16549223 | B32: Sc1 | C32: =(C2+C8+C14)/3 -> 2228.2002 | D32: =(D2+D8+D14)/3 -> 849.90789 | E32: =(F2+F8+F14)/3 -> 1470 | F32: =(G2+G8+G14)/3 -> 14327.9 | G32: =(H2+H8+H14)/3 -> 364 | H32: =(I2+I8+I14)/3 -> 3927.9452 | I32: =(K2+K8+K14)/3 -> 15.68 | J32: =(L2+L8+L14)/3 -> 471.71835 | K32: =(N2+N8+N14)/3 -> 844.65 | L32: =(O2+O8+O14)/3 -> 369.22
A33: =(D23-D26)/D23 -> 0.10802486 | B33: Sc2 | C33: =(C3+C9+C15)/3 -> 2228.2002 | D33: =(D3+D9+D15)/3 -> 849.90789 | E33: =(F3+F9+F15)/3 -> 1470 | F33: =(G3+G9+G15)/3 -> 14327.9 | G33: =(H3+H9+H15)/3 -> 364 | H33: =(I3+I9+I15)/3 -> 3927.9452 | I33: =(K3+K9+K15)/3 -> 15.68 | J33: =(L3+L9+L15)/3 -> 471.71835 | K33: =(N3+N9+N15)/3 -> 844.65 | L33: =(O3+O9+O15)/3 -> 369.22 | M33: =(C33-C32)/C32 -> 0 | N33: =(D33-D32)/D32 -> 0 | O33: =(E33-E32)/E32 -> 0 | P33: =(F33-F32)/F32 -> 0 | Q33: =(G33-G32)/G32 -> 0 | R33: =(H33-H32)/H32 -> 0 | S33: =(I33-I32)/I32 -> 0 | T33: =(J33-J32)/J32 -> 0
A34: =(D23-D25)/D23 -> 0.083887661 | B34: Sc3 | C34: =(C4+C10+C16)/3 -> 1382.2123 | D34: =(D4+D10+D16)/3 -> 594.10167 | E34: =(F4+F10+F16)/3 -> 1470 | F34: =(G4+G10+G16)/3 -> 12751.8 | G34: =(H4+H10+H16)/3 -> 352 | H34: =(I4+I10+I16)/3 -> 3830.755 | I34: =(K4+K10+K16)/3 -> 15.68 | J34: =(L4+L10+L16)/3 -> 453.07945 | K34: =(N4+N10+N16)/3 -> 844.65 | L34: =(O4+O10+O16)/3 -> 369.22 | M34: =((C34-C32)/C32)*100 -> -37.967319 | N34: =((D34-D32)/D32)*100 -> -30.098111 | O34: =((E34-E32)/E32)*100 -> 0 | P34: =((F34-F32)/F32)*100 -> -11.000216 | Q34: =((G34-G32)/G32)*100 -> -3.2967033 | R34: =((H34-H32)/H32)*100 -> -2.4743248 | S34: =((I34-I32)/I32)*100 -> 0 | T34: =((J34-J32)/J32)*100 -> -3.9512777
B35: Sc4 | C35: =(C5+C11+C17)/3 -> 0 | D35: =(D5+D11+D17)/3 -> 892.36506 | E35: =(F5+F11+F17)/3 -> 1470 | F35: =(G5+G11+G17)/3 -> 12751.8 | G35: =(H5+H11+H17)/3 -> 462 | H35: =(I5+I11+I17)/3 -> 3235.8424 | I35: =(K5+K11+K17)/3 -> 0 | J35: =(L5+L11+L17)/3 -> 392.85804 | K35: =(N5+N11+N17)/3 -> 844.65 | L35: =(O5+O11+O17)/3 -> 369.22 | M35: =((C35-C32)/C32)*100 -> -100 | N35: =((D35-D32)/D32)*100 -> 4.9955021 | O35: =((E35-E32)/E32)*100 -> 0 | P35: =((F35-F32)/F32)*100 -> -11.000216 | Q35: =((G35-G32)/G32)*100 -> 26.923077 | R35: =((H35-H32)/H32)*100 -> -17.61997 | S35: =((I35-I32)/I32)*100 -> -100 | T35: =((J35-J32)/J32)*100 -> -16.717668
B36: Sc5 | C36: =(C6+C12+C18)/3 -> 0 | D36: =(D6+D12+D18)/3 -> 892.36506 | E36: =(F6+F12+F18)/3 -> 1470 | F36: =(G6+G12+G18)/3 -> 11597.29 | G36: =(H6+H12+H18)/3 -> 462 | H36: =(I6+I12+I18)/3 -> 3235.8424 | I36: =(K6+K12+K18)/3 -> 0 | J36: =(L6+L12+L18)/3 -> 392.85804 | K36: =(N6+N12+N18)/3 -> 844.65 | L36: =(O6+O12+O18)/3 -> 369.22 | M36: =((C36-C32)/C32)*100 -> -100 | N36: =((D36-D32)/D32)*100 -> 4.9955021 | O36: =((E36-E32)/E32)*100 -> 0 | P36: =((F36-F32)/F32)*100 -> -19.057995 | Q36: =((G36-G32)/G32)*100 -> 26.923077 | R36: =((H36-H32)/H32)*100 -> -17.61997 | S36: =((I36-I32)/I32)*100 -> -100 | T36: =((J36-J32)/J32)*100 -> -16.717668
B37: Sc6 | C37: =(C7+C13+C19)/3 -> 0 | D37: =(D7+D13+D19)/3 -> 892.36506 | E37: =(F7+F13+F19)/3 -> 1470 | F37: =(G7+G13+G19)/3 -> 10809.358 | G37: =(H7+H13+H19)/3 -> 462 | H37: =(I7+I13+I19)/3 -> 3235.8424 | I37: =(K7+K13+K19)/3 -> 0 | J37: =(L7+L13+L19)/3 -> 392.85804 | K37: =(N7+N13+N19)/3 -> 844.65 | L37: =(O7+O13+O19)/3 -> 369.22 | M37: =((C37-C32)/C32)*100 -> -100 | N37: =((D37-D32)/D32)*100 -> 4.9955021 | O37: =((E37-E32)/E32)*100 -> 0 | P37: =((F37-F32)/F32)*100 -> -24.557277 | Q37: =((G37-G32)/G32)*100 -> 26.923077 | R37: =((H37-H32)/H32)*100 -> -17.61997 | S37: =((I37-I32)/I32)*100 -> -100 | T37: =((J37-J32)/J32)*100 -> -16.717668
D38: =C32+H32 -> 6156.1454 | E38: =(D38*100)/H23 -> 24.754073 | F38: =AVERAGE(F32:F37) -> 12761.008 | G38: =AVERAGE(G32:G37) -> 411 | H38: =AVERAGE(H32:H37) -> 3565.6954 | O38: =AVERAGE(O35:O37) -> 0 | P38: =AVERAGE(P35:P37) -> -18.205163 | Q38: =AVERAGE(Q35:Q37) -> 26.923077 | R38: =AVERAGE(R35:R37) -> -17.61997
D39: =H38 -> 3565.6954 | E39: =(D39*100)/H24 -> 14.337785 | F39: =(F38*100)/D30 -> 70.085764 | G39: =(G38*100)/H30 -> 1.9263783 | H39: =(H38*100)/H30 -> 16.712599 | K39: =SUM(I32:J32) -> 487.39835
H40: =(H38*100)/D30 -> 19.583444 | J40: =SUM(C32:L32) -> 24869.222
...

Sheet System
A1: Rep | B1: Scenarios | C1: Energy use in field operations | D1: Energy use in production Inputs | E1: Energy use in crop management | F1: Energy use in Harvesting and Threshing | G1: Energy use in transportation | H1: Total energy use in productions | I1: Direct energy | J1: Indirect energy | K1: Renewable energy | L1: Non-renewable energy | M1: Total energy input | N1: Grain energy output | O1: Energy out in the harvested total biomass (grain + straw) | P1: Net energy | Q1: Grain specific energy | R1: Total specific energy | AI1: Direct energy MJ ha−1 | AJ1: Indirect energy MJ ha−1 | AK1: Renewable energy (MJ ha-1) | AL1: Non-renewable energy (kg MJ-1) | AM1: Total energy input ×103 MJ ha−1 | AN1: Grain energy output | AO1: Total energy output (Energy in the harvested total biomass (grain + straw) ×103 MJ ha−1 | AP1: Net energy ×103 MJ ha−1 | AQ1: Grain specific energy | AR1: Total specific energy
A2: 1 | B2: 1 | C2: =(Rice!F2+Wheat!E2) -> 7413.8689 | D2: =Rice!K2+Wheat!J2 -> 56433.769 | E2: =Rice!N2+Wheat!M2 -> 2811.2044 | F2: =Rice!O2+Wheat!N2 -> 1970.85 | G2: =Rice!P2+Wheat!O2 -> 754.22 | H2: =(Rice!R2+Wheat!P2) -> 69383.912 | I2: =Rice!$S$2+Wheat!AE2 -> 36297.162 | J2: =Rice!$T$2+Wheat!AF2 -> 33086.75 | K2: =Rice!$Y$2+Wheat!AK2 -> 4464.9544 | L2: =Rice!$Z$2+Wheat!AL2 -> 64918.958 | M2: =Rice!$R$2+Wheat!P2 -> 69383.912 | N2: =Rice!AF2+Wheat!AR2 -> 174621.3 | O2: =Rice!AG2+Wheat!AS2 -> 376927.5 | P2: =O2-M2 -> 307543.59 | Q2: =N2/M2 -> 2.5167405 | R2: =O2/M2 -> 5.4324913 | U2: =(M2+M8+M14)/3 -> 69521.411 | V2: =(N2+N8+N14)/3 -> 173268.9 | W2: =(O2+O8+O14)/3 -> 371241.45 | X2: =(P2+P8+P14)/3 -> 301720.04 | Y2: =(Q2+Q8+Q14)/3 -> 2.4926428 | AI2: =Rice!S2+Wheat!AE2 -> 36297.162 | AJ2: =Rice!T2+Wheat!AF2 -> 33086.75 | AK2: =Rice!Y2+Wheat!AK2 -> 4464.9544 | AL2: =Rice!Z2+Wheat!AL2 -> 64918.958 | AM2: =Rice!U2+Wheat!AG2 -> 69383.912 | AN2: =Rice!AF2+Wheat!AR2 -> 174621.3 | AO2: =Rice!AG2+Wheat!AS2 -> 376927.5 | AP2: =AO2-AM2 -> 307543.59 | AQ2: =AN2/AM2 -> 2.5167405 | AR2: =AO2/AM2 -> 5.4324913
A3: 1 | B3: 2 | C3: =(Rice!F3+Wheat!E3) -> 7413.8689 | D3: =Rice!K3+Wheat!J3 -> 56433.769 | E3: =Rice!N3+Wheat!M3 -> 2811.2044 | F3: =Rice!O3+Wheat!N3 -> 1970.85 | G3: =Rice!P3+Wheat!O3 -> 754.22 | H3: =(Rice!R3+Wheat!P3) -> 69383.912 | I3: =Rice!$S$2+Wheat!AE3 -> 36297.162 | J3: =Rice!$T$2+Wheat!AF3 -> 33086.75 | K3: =Rice!$Y$2+Wheat!AK3 -> 4464.9544 | L3: =Rice!$Z$2+Wheat!AL3 -> 64918.958 | M3: =Rice!$R$2+Wheat!P3 -> 69383.912 | N3: =Rice!AF3+Wheat!AR3 -> 177002.7 | O3: =Rice!AG3+Wheat!AS3 -> 382295.01 | P3: =O3-M3 -> 312911.1 | Q3: =N3/M3 -> 2.5510625 | R3: =O3/M3 -> 5.5098508 | U3: =(M3+M9+M15)/3 -> 69521.411 | V3: =(N3+N9+N15)/3 -> 176390.2 | W3: =(O3+O9+O15)/3 -> 376756.48 | X3: =(P3+P9+P15)/3 -> 307235.07 | Y3: =(Q3+Q9+Q15)/3 -> 2.5373751 | AI3: =Rice!S3+Wheat!AE3 -> 36297.162 | AJ3: =Rice!T3+Wheat!AF3 -> 33086.75 | AK3: =Rice!Y3+Wheat!AK3 -> 4464.9544 | AL3: =Rice!Z3+Wheat!AL3 -> 64918.958 | AM3: =Rice!U3+Wheat!AG3 -> 69383.912 | AN3: =Rice!AF3+Wheat!AR3 -> 177002.7 | AO3: =Rice!AG3+Wheat!AS3 -> 382295.01 | AP3: =AO3-AM3 -> 312911.1 | AQ3: =AN3/AM3 -> 2.5510625 | AR3: =AO3/AM3 -> 5.5098508
A4: 1 | B4: 3 | C4: =(Rice!F4+Wheat!E4) -> 3708.739 | D4: =Rice!K4+Wheat!J4 -> 49101.272 | E4: =Rice!N4+Wheat!M4 -> 2414.5302 | F4: =Rice!O4+Wheat!N4 -> 1970.85 | G4: =Rice!P4+Wheat!O4 -> 754.22 | H4: =(Rice!R4+Wheat!P4) -> 57949.611 | I4: =Rice!$S$2+Wheat!AE4 -> 34945.869 | J4: =Rice!$T$2+Wheat!AF4 -> 31498.65 | K4: =Rice!$Y$2+Wheat!AK4 -> 4432.9484 | L4: =Rice!$Z$2+Wheat!AL4 -> 62011.571 | M4: =Rice!$R$2+Wheat!P4 -> 66444.519 | N4: =Rice!AF4+Wheat!AR4 -> 172607.4 | O4: =Rice!AG4+Wheat!AS4 -> 377804.2 | P4: =O4-M4 -> 311359.68 | Q4: =N4/M4 -> 2.5977673 | R4: =O4/M4 -> 5.68601 | U4: =(M4+M10+M16)/3 -> 66715.688 | V4: =(N4+N10+N16)/3 -> 176826.3 | W4: =(O4+O10+O16)/3 -> 379297.55 | X4: =(P4+P10+P16)/3 -> 312581.86 | Y4: =(Q4+Q10+Q16)/3 -> 2.6505663 | AI4: =Rice!S4+Wheat!AE4 -> 29256.111 | AJ4: =Rice!T4+Wheat!AF4 -> 28693.5 | AK4: =Rice!Y4+Wheat!AK4 -> 4178.5302 | AL4: =Rice!Z4+Wheat!AL4 -> 53771.081 | AM4: =Rice!U4+Wheat!AG4 -> 57949.611 | AN4: =Rice!AF4+Wheat!AR4 -> 172607.4 | AO4: =Rice!AG4+Wheat!AS4 -> 377804.2 | AP4: =AO4-AM4 -> 319854.59 | AQ4: =AN4/AM4 -> 2.9785774 | AR4: =AO4/AM4 -> 6.5195295
A5: 1 | B5: 4 | C5: =(Rice!F5+Wheat!E5) -> 2624.7901 | D5: =Rice!K5+Wheat!J5 -> 47725.331 | E5: =Rice!N5+Wheat!M5 -> 2240.7368 | F5: =Rice!O5+Wheat!N5 -> 1970.85 | G5: =Rice!P5+Wheat!O5 -> 754.22 | H5: =(Rice!R5+Wheat!P5) -> 55315.928 | I5: =Rice!$S$2+Wheat!AE5 -> 33203.229 | J5: =Rice!$T$2+Wheat!AF5 -> 31608.65 | K5: =Rice!$Y$2+Wheat!AK5 -> 4358.2593 | L5: =Rice!$Z$2+Wheat!AL5 -> 60453.62 | M5: =Rice!$R$2+Wheat!P5 -> 64811.879 | N5: =Rice!AF5+Wheat!AR5 -> 181706.7 | O5: =Rice!AG5+Wheat!AS5 -> 394484.65 | P5: =O5-M5 -> 329672.77 | Q5: =N5/M5 -> 2.8036018 | R5: =O5/M5 -> 6.0866104 | U5: =(M5+M11+M17)/3 -> 65070.925 | V5: =(N5+N11+N17)/3 -> 180545.4 | W5: =(O5+O11+O17)/3 -> 391659.22 | X5: =(P5+P11+P17)/3 -> 326588.29 | Y5: =(Q5+Q11+Q17)/3 -> 2.774738 | AI5: =Rice!S5+Wheat!AE5 -> 26522.428 | AJ5: =Rice!T5+Wheat!AF5 -> 28793.5 | AK5: =Rice!Y5+Wheat!AK5 -> 4004.7368 | AL5: =Rice!Z5+Wheat!AL5 -> 51311.191 | AM5: =Rice!U5+Wheat!AG5 -> 55315.928 | AN5: =Rice!AF5+Wheat!AR5 -> 181706.7 | AO5: =Rice!AG5+Wheat!AS5 -> 394484.65 | AP5: =AO5-AM5 -> 339168.73 | AQ5: =AN5/AM5 -> 3.2848893 | AR5: =AO5/AM5 -> 7.1314839
